Workbook

Sheet Invoices
B2: Total | H2: =SUM(H5:H2997) -> 1865516.3 | I2: =SUM(I5:I2997) -> 1804280.6 | J2: =SUM(J5:J2997) -> 12996.923 | K2: =SUM(K5:K2997) -> 1817277.5 | L2: =SUM(L5:L2997) -> 272620.7 | M2: =SUM(M5:M2997) -> 2089898.2
B4: ID | C4: Invoice Date | D4: EOMONTH | E4: Invoice ID | F4: Contractor | G4: Description | H4: Contract Amt. (NET + CNPAIA) (€) | I4: NET (€) | J4: CNPAIA (€) | K4: Invoiced Amt. (NET + CNPAIA) (€) | L4: VAT Invoiced | M4: Gross Invoiced Amt. (€) | N4: Contract Approved? | O4: Invoice Received? | P4: Invoice Approved | Q4: Approved by (UHG/Michiel) | R4: Paid?
B5: 1 | C5: 45716 | D5: =EOMONTH(C5,0) -> 45716 | E5: 2003066 | F5: Stylt | G5: The Usual Hotel Corona Competition+ Travel costs | H5: 4000 | I5: 4000 | J5: 0 | K5: =SUM(I5,J5) -> 4000 | L5: 0 | M5: =SUM(K5,L5) -> 4000 | N5: 1 | O5: 1 | P5: 1 | Q5: 1 | R5: 1 | T5: =K5-'[1]Contracts & Invoices'!R12 -> 0
B6: 2 | C6: 45729 | D6: =EOMONTH(C6,0) -> 45747 | E6: 2025/072 | F6: Joi-Design | G6: Interior design planning services | H6: 2500 | I6: 2500 | J6: 0 | K6: =SUM(I6,J6) -> 2500 | L6: 0 | M6: =SUM(K6,L6) -> 2500 | N6: 1 | O6: 1 | P6: 1 | Q6: 1 | R6: 1 | T6: =K6-'[1]Contracts & Invoices'!R13 -> 0
B7: 3 | C7: 45745 | D7: =EOMONTH(C7,0) -> 45747 | E7: n.9/001 | F7: Rizoma | G7: Renovation of Hotel Corona-Interior Contest | H7: 2600 | I7: 2500 | J7: 100 | K7: =SUM(I7,J7) -> 2600 | L7: 572 | M7: =SUM(K7,L7) -> 3172 | N7: 1 | O7: 1 | P7: 1 | Q7: 1 | R7: 1 | T7: =K7-'[1]Contracts & Invoices'!R14 -> 0
B8: 4 | C8: 45807 | D8: =EOMONTH(C8,0) -> 45808 | E8: VMI25_00270 | F8: Artelia | G8: Project Management | H8: 29200 | I8: 29200 | J8: 0 | K8: =SUM(I8,J8) -> 29200 | L8: 6424 | M8: =SUM(K8,L8) -> 35624 | N8: 1 | O8: 1 | P8: 1 | Q8: 1 | R8: 1 | T8: =K8-'[1]Contracts & Invoices'!R15 -> 0
B9: 5 | C9: 45807 | D9: =EOMONTH(C9,0) -> 45808 | E9: VMI25_00270 | F9: Artelia | G9: Construction Management | H9: 8000 | I9: 8000 | J9: 0 | K9: =SUM(I9,J9) -> 8000 | L9: 1760 | M9: =SUM(K9,L9) -> 9760 | N9: 1 | O9: 1 | P9: 1 | Q9: 1 | R9: 1 | T9: =K9-'[1]Contracts & Invoices'!R16 -> 0
B10: 6 | C10: 45807 | D10: =EOMONTH(C10,0) -> 45808 | E10: VMI25_00270 | F10: Artelia | G10: Multidisciplinary Engineering Design | H10: 28080 | I10: 27000 | J10: 0 | K10: =SUM(I10,J10) -> 27000 | L10: 5940 | M10: =SUM(K10,L10) -> 32940 | N10: 1 | O10: 1 | P10: 1 | Q10: 1 | R10: 1 | T10: =K10-'[1]Contracts & Invoices'!R17 -> 0
B11: 7 | C11: 45821 | D11: =EOMONTH(C11,0) -> 45838 | E11: VMI25_00444 | F11: Artelia /Stylt | G11: Phase 1 - 4 | H11: 76240 | I11: 76240 | J11: 0 | K11: =SUM(I11,J11) -> 76240 | L11: 16772.8 | M11: =SUM(K11,L11) -> 93012.8 | N11: 1 | O11: 1 | P11: 1 | Q11: 1 | R11: 1 | T11: =K11-'[1]Contracts & Invoices'!R18 -> 0
B12: 8 | C12: 45838 | D12: =EOMONTH(C12,0) -> 45838 | E12: VMI25_00356 | F12: Artelia | G12: Project Management | H12: 11426.087 | I12: 11350.44 | J12: 0 | K12: =SUM(I12,J12) -> 11350.44 | L12: 2497.0968 | M12: =SUM(K12,L12) -> 13847.537 | N12: 1 | O12: 1 | P12: 1 | Q12: 1 | R12: 1 | T12: =K12-'[1]Contracts & Invoices'!R19 -> 0
B13: 9 | C13: 45838 | D13: =EOMONTH(C13,0) -> 45838 | E13: VMI25_00356 | F13: Artelia | G13: Construction Management | H13: 3130.4348 | I13: 3304.35 | J13: 0 | K13: =SUM(I13,J13) -> 3304.35 | L13: 726.957 | M13: =SUM(K13,L13) -> 4031.307 | N13: 1 | O13: 1 | P13: 1 | Q13: 1 | R13: 1 | T13: =K13-'[1]Contracts & Invoices'!R20 -> 0
B14: 10 | C14: 45838 | D14: =EOMONTH(C14,0) -> 45838 | E14: VMI25_00356 | F14: Artelia | G14: Multidisciplinary Engineering Design | H14: 84240 | I14: 76950 | J14: 3078 | K14: =SUM(I14,J14) -> 80028 | L14: 17606.16 | M14: =SUM(K14,L14) -> 97634.16 | N14: 1 | O14: 1 | P14: 1 | Q14: 1 | R14: 1 | T14: =K14-'[1]Contracts & Invoices'!R21 -> 0
B15: 11 | C15: 45838 | D15: =EOMONTH(C15,0) -> 45838 | E15: VMI25_00356 | F15: Artelia | G15: BREEAM Consultancy | H15: 2600 | I15: 2375 | J15: 95 | K15: =SUM(I15,J15) -> 2470 | L15: 543.4 | M15: =SUM(K15,L15) -> 3013.4 | N15: 1 | O15: 1 | P15: 1 | Q15: 1 | R15: 1 | T15: =K15-'[1]Contracts & Invoices'!R22 -> 0
B16: 12 | C16: 45852 | D16: =EOMONTH(C16,0) -> 45869 | E16: 146 | F16: Gaia Group | G16: Rilievi Laser Scanner 3D, modellazione 3D Piano Terra e 2D | H16: 16000 | I16: 16000 | J16: 0 | K16: =SUM(I16,J16) -> 16000 | L16: 3520 | M16: =SUM(K16,L16) -> 19520 | N16: 1 | O16: 1 | P16: 1 | Q16: 1 | R16: 1 | T16: =K16-'[1]Contracts & Invoices'!R23 -> 0
... B20: 16 | C20: 45898 | D20: =EOMONTH(C20,0) -> 45900 | E20: VMI25_00445 | F20: Artelia | G20: Multidisciplinary Engineering Design | H20: 0 | I20: 0 | J20: 0 | K20: =SUM(I20,J20) -> 0 | L20: 0 | M20: =SUM(K20,L20) -> 0 | N20: 1 | O20: 1 | P20: 1 | Q20: 1 | R20: 1 | T20: =K20-'[1]Contracts & Invoices'!R27 -> 0
B21: 17 | C21: 45908 | D21: =EOMONTH(C21,0) -> 45930 | E21: 3000103 | F21: HC /Stylt | G21: Travel Costs | H21: 4036 | I21: 4036 | J21: 0 | K21: =SUM(I21,J21) -> 4036 | L21: 0 | M21: =SUM(K21,L21) -> 4036 | N21: 1 | O21: 1 | P21: 1 | Q21: 1 | R21: 1 | T21: =K21-'[1]Contracts & Invoices'!R28 -> 0
B22: 18 | C22: 45916 | D22: =EOMONTH(C22,0) -> 45930 | E22: 075_2025 | F22: Sese | G22: Mock up room n.01 | H22: 14046 | I22: 14046 | J22: 0 | K22: =SUM(I22,J22) -> 14046 | L22: 3090.12 | M22: =SUM(K22,L22) -> 17136.12 | N22: 1 | O22: 1 | P22: 1 | Q22: 1 | R22: 0 | T22: =K22-'[1]Contracts & Invoices'!R29 -> 0
B23: 19 | C23: 45917 | D23: =EOMONTH(C23,0) -> 45930 | E23: 3000105 | F23: HC /Stylt | G23: Extra Costs | H23: 6120 | I23: 6120 | J23: 0 | K23: =SUM(I23,J23) -> 6120 | L23: 0 | M23: =SUM(K23,L23) -> 6120 | N23: 1 | O23: 1 | P23: 1 | Q23: 1 | R23: 0 | T23: =K23-'[1]Contracts & Invoices'!R30 -> 0
B24: 20 | C24: 45922 | D24: =EOMONTH(C24,0) -> 45930 | E24: VMI25_00510 | F24: Artelia /Stylt | G24: Phase 1 - 4 | H24: 57180 | I24: 57180 | J24: 0 | K24: =SUM(I24,J24) -> 57180 | L24: 12579.6 | M24: =SUM(K24,L24) -> 69759.6 | N24: 1 | O24: 1 | P24: 1 | Q24: 1 | R24: 1 | T24: =K24-'[1]Contracts & Invoices'!R31 -> 0
B25: 21 | C25: 45922 | D25: =EOMONTH(C25,0) -> 45930 | E25: VMI25_00509 | F25: Artelia /Stylt | G25: Phase 1 - 4 | H25: 38120 | I25: 38120 | J25: 0 | K25: =SUM(I25,J25) -> 38120 | L25: 8386.4 | M25: =SUM(K25,L25) -> 46506.4 | N25: 1 | O25: 1 | P25: 1 | Q25: 1 | R25: 1 | T25: =K25-'[1]Contracts & Invoices'!R32 -> 0
B26: 22 | C26: 45922 | D26: =EOMONTH(C26,0) -> 45930 | E26: VMI25_00511 | F26: Artelia | G26: Project Management | H26: 11426.087 | I26: 11426.087 | J26: 0 | K26: =SUM(I26,J26) -> 11426.087 | L26: 2513.7391 | M26: =SUM(K26,L26) -> 13939.826 | N26: 1 | O26: 1 | P26: 1 | Q26: 1 | R26: 1 | T26: =K26-'[1]Contracts & Invoices'!R33 -> 0
B27: 23 | C27: 45922 | D27: =EOMONTH(C27,0) -> 45930 | E27: VMI25_00511 | F27: Artelia | G27: Project Management | H27: 11426.087 | I27: 11426.087 | J27: 0 | K27: =SUM(I27,J27) -> 11426.087 | L27: 2513.7391 | M27: =SUM(K27,L27) -> 13939.826 | N27: 1 | O27: 1 | P27: 1 | Q27: 1 | R27: 1 | T27: =K27-'[1]Contracts & Invoices'!R34 -> 0
B28: 24 | C28: 45922 | D28: =EOMONTH(C28,0) -> 45930 | E28: VMI25_00511 | F28: Artelia | G28: Project Management | H28: 0 | I28: 0 | J28: 0 | K28: =SUM(I28,J28) -> 0 | L28: 0.076521739 | M28: =SUM(K28,L28) -> 0.076521739 | N28: 1 | O28: 1 | P28: 1 | Q28: 1 | R28: 1 | T28: =K28-'[1]Contracts & Invoices'!R35 -> 0
B29: 25 | C29: 45922 | D29: =EOMONTH(C29,0) -> 45930 | E29: VMI25_00511 | F29: Artelia | G29: Construction Management | H29: 3130.4348 | I29: 3130.4348 | J29: 0 | K29: =SUM(I29,J29) -> 3130.4348 | L29: 688.69565 | M29: =SUM(K29,L29) -> 3819.1304 | N29: 1 | O29: 1 | P29: 1 | Q29: 1 | R29: 1 | T29: =K29-'[1]Contracts & Invoices'!R36 -> 0
B30: 26 | C30: 45922 | D30: =EOMONTH(C30,0) -> 45930 | E30: VMI25_00511 | F30: Artelia | G30: Construction Management | H30: 3130.4348 | I30: 3130.4348 | J30: 0 | K30: =SUM(I30,J30) -> 3130.4348 | L30: 688.69565 | M30: =SUM(K30,L30) -> 3819.1304 | N30: 1 | O30: 1 | P30: 1 | Q30: 1 | R30: 1 | T30: =K30-'[1]Contracts & Invoices'!R37 -> 0
B31: 27 | C31: 45922 | D31: =EOMONTH(C31,0) -> 45930 | E31: VMI25_00511 | F31: Artelia | G31: Construction Management | H31: 0 | I31: 0 | J31: 0 | K31: =SUM(I31,J31) -> 0 | L31: 2513.7391 | M31: =SUM(K31,L31) -> 2513.7391 | N31: 1 | O31: 1 | P31: 1 | Q31: 1 | R31: 1 | T31: =K31-'[1]Contracts & Invoices'!R38 -> 0
B32: 28 | C32: 45922 | D32: =EOMONTH(C32,0) -> 45930 | E32: VMI25_00511 | F32: Artelia | G32: Multidisciplinary Engineering Design | H32: 84240 | I32: 81000 | J32: 3240 | K32: =SUM(I32,J32) -> 84240 | L32: 18532.8 | M32: =SUM(K32,L32) -> 102772.8 | N32: 1 | O32: 1 | P32: 1 | Q32: 1 | R32: 1 | T32: =K32-'[1]Contracts & Invoices'!R39 -> 0
B33: 29 | C33: 45922 | D33: =EOMONTH(C33,0) -> 45930 | E33: VMI25_00511 | F33: Artelia | G33: Multidisciplinary Engineering Design | H33: 0 | I33: 4050 | J33: 162 | K33: =SUM(I33,J33) -> 4212 | L33: 926.64 | M33: =SUM(K33,L33) -> 5138.64 | N33: 1 | O33: 1 | P33: 1 | Q33: 1 | R33: 1 | T33: =K33-'[1]Contracts & Invoices'!R40 -> 0
B34: 30 | C34: 45922 | D34: =EOMONTH(C34,0) -> 45930 | E34: VMI25_00511 | F34: Artelia | G34: ID Coordination | H34: 869.56522 | I34: 869.56522 | J34: 0 | K34: =SUM(I34,J34) -> 869.56522 | L34: 191.30435 | M34: =SUM(K34,L34) -> 1060.8696 | N34: 1 | O34: 1 | P34: 1 | Q34: 1 | R34: 1 | T34: =K34-'[1]Contracts & Invoices'!R41 -> 0
B35: 31 | C35: 45922 | D35: =EOMONTH(C35,0) -> 45930 | E35: VMI25_00511 | F35: Artelia | G35: ID Coordination | H35: 869.56522 | I35: 869.56522 | J35: 0 | K35: =SUM(I35,J35) -> 869.56522 | L35: 191.30435 | M35: =SUM(K35,L35) -> 1060.8696 | N35: 1 | O35: 1 | P35: 1 | Q35: 1 | R35: 1 | T35: =K35-'[1]Contracts & Invoices'!R42 -> 0
... B43: 39 | C43: 45930 | D43: =EOMONTH(C43,0) -> 45930 | E43: B250410 | F43: Contract | G43: Mock up room n.01 | H43: 16716.28 | I43: 16716.28 | J43: 0 | K43: =SUM(I43,J43) -> 16716.28 | L43: 3677.5816 | M43: =SUM(K43,L43) -> 20393.862 | N43: 1 | O43: 1 | P43: 1 | Q43: 1 | R43: 0 | T43: =K43-'[1]Contracts & Invoices'!R50 -> 0
B44: 40 | C44: 45938 | D44: =EOMONTH(C44,0) -> 45961 | E44: 3000129 | F44: HC /Stylt | G44: Extra Costs | H44: 5040 | I44: 5040 | J44: 0 | K44: =SUM(I44,J44) -> 5040 | L44: 0 | M44: =SUM(K44,L44) -> 5040 | N44: 1 | O44: 1 | P44: 1 | Q44: 1 | R44: 0 | T44: =K44-'[1]Contracts & Invoices'!R51 -> 0
B45: 41 | C45: 45938 | D45: =EOMONTH(C45,0) -> 45961 | E45: 3000126 | F45: HC /Stylt | G45: Extra Costs | H45: 720 | I45: 720 | J45: 0 | K45: =SUM(I45,J45) -> 720 | L45: 0 | M45: =SUM(K45,L45) -> 720 | N45: 1 | O45: 1 | P45: 1 | Q45: 1 | R45: 1 | T45: =K45-'[1]Contracts & Invoices'!R52 -> 0
B46: 42 | C46: 45945 | D46: =EOMONTH(C46,0) -> 45961 | E46: - | F46: Municipality | G46: Comune di Firenze | H46: 16 | I46: 16 | J46: 0 | K46: =SUM(I46,J46) -> 16 | L46: 0 | M46: =SUM(K46,L46) -> 16 | N46: 1 | O46: 1 | P46: 1 | Q46: 1 | R46: 1 | T46: =K46-'[1]Contracts & Invoices'!R53 -> 0
B47: 43 | C47: 45957 | D47: =EOMONTH(C47,0) -> 45961 | E47: 3000134 | F47: HC /Stylt | G47: Extra Costs | H47: -720 | I47: -720 | J47: 0 | K47: =SUM(I47,J47) -> -720 | L47: 0 | M47: =SUM(K47,L47) -> -720 | N47: 1 | O47: 1 | P47: 1 | Q47: 1 | R47: 1 | T47: =K47-'[1]Contracts & Invoices'!R54 -> 0
B48: 44 | C48: 45958 | D48: =EOMONTH(C48,0) -> 45961 | E48: - | F48: Municipality_Asl | G48: Comune di Firenze | H48: 1056 | I48: 1056 | J48: 0 | K48: =SUM(I48,J48) -> 1056 | L48: 0 | M48: =SUM(K48,L48) -> 1056 | N48: 1 | O48: 1 | P48: 1 | Q48: 1 | R48: 1 | T48: =K48-'[1]Contracts & Invoices'!R55 -> 0
B49: 45 | C49: 45961 | D49: =EOMONTH(C49,0) -> 45961 | E49: VMI25_00595 | F49: Artelia | G49: Project Management | H49: 11426.087 | I49: 11426.087 | J49: 0 | K49: =SUM(I49,J49) -> 11426.087 | L49: 2513.7391 | M49: =SUM(K49,L49) -> 13939.826 | N49: 1 | O49: 1 | P49: 1 | Q49: 1 | R49: 1 | T49: =K49-'[1]Contracts & Invoices'!R56 -> 0
B50: 46 | C50: 45961 | D50: =EOMONTH(C50,0) -> 45961 | E50: VMI25_00595 | F50: Artelia | G50: Construction Management | H50: 3130.4348 | I50: 3130.4348 | J50: 0 | K50: =SUM(I50,J50) -> 3130.4348 | L50: 688.69565 | M50: =SUM(K50,L50) -> 3819.1304 | N50: 1 | O50: 1 | P50: 1 | Q50: 1 | R50: 1 | T50: =K50-'[1]Contracts & Invoices'!R57 -> 0
B51: 47 | C51: 45961 | D51: =EOMONTH(C51,0) -> 45961 | E51: VMI25_00595 | F51: Artelia | G51: ID Coordination | H51: 869.56522 | I51: 869.56522 | J51: 0 | K51: =SUM(I51,J51) -> 869.56522 | L51: 191.30435 | M51: =SUM(K51,L51) -> 1060.8696 | N51: 1 | O51: 1 | P51: 1 | Q51: 1 | R51: 1 | T51: =K51-'[1]Contracts & Invoices'!R58 -> 0
B52: 48 | C52: 45965 | D52: =EOMONTH(C52,0) -> 45991 | E52: 3000143 | F52: HC /Stylt | G52: Extra Costs | H52: 1680 | I52: 1680 | J52: 0 | K52: =SUM(I52,J52) -> 1680 | L52: 0 | M52: =SUM(K52,L52) -> 1680 | N52: 1 | O52: 1 | P52: 1 | Q52: 1 | R52: 1 | T52: =K52-'[1]Contracts & Invoices'!R59 -> 0
...

Sheet Model - Capex
B2: To Date | D2: 46112
B3: Period | F3: 0 | G3: 0 | H3: 0 | I3: =F3+1 -> 1 | J3: =G3+1 -> 1 | K3: =H3+1 -> 1 | L3: =I3+1 -> 2 | M3: =J3+1 -> 2 | N3: =K3+1 -> 2 | O3: =L3+1 -> 3 | P3: =M3+1 -> 3 | ... AL3: =AI3+1 -> 10 | AN3: 0 | AO3: =AN3+1 -> 1 | AP3: =AO3+1 -> 2 | AQ3: =AP3+1 -> 3 | AR3: =AQ3+1 -> 4 | AS3: =AR3+1 -> 5 | AT3: =AS3+1 -> 6 | AU3: =AT3+1 -> 7 | AV3: =AU3+1 -> 8 | ... AX3: =AW3+1 -> 10
B4: BoP | F4: 45658 | G4: =F5+1 -> 45689 | H4: =G5+1 -> 45717 | I4: =H5+1 -> 45748 | J4: =I5+1 -> 45778 | K4: =J5+1 -> 45809 | L4: =K5+1 -> 45839 | M4: =L5+1 -> 45870 | N4: =M5+1 -> 45901 | ... AL4: =AK5+1 -> 46631 | AN4: 45658 | AO4: =AN5+1 -> 45748 | AP4: =AO5+1 -> 45839 | AQ4: =AP5+1 -> 45931 | AR4: =AQ5+1 -> 46023 | AS4: =AR5+1 -> 46113 | AT4: =AS5+1 -> 46204 | AU4: =AT5+1 -> 46296 | AV4: =AU5+1 -> 46388 | ... AX4: =AW5+1 -> 46569
B5: EoP | D5: Total | F5: 45688 | G5: =EOMONTH(F5,1) -> 45716 | H5: =EOMONTH(G5,1) -> 45747 | I5: =EOMONTH(H5,1) -> 45777 | J5: =EOMONTH(I5,1) -> 45808 | K5: =EOMONTH(J5,1) -> 45838 | L5: =EOMONTH(K5,1) -> 45869 | M5: =EOMONTH(L5,1) -> 45900 | N5: =EOMONTH(M5,1) -> 45930 | ... AL5: =EOMONTH(AK5,1) -> 46660 | AN5: 45747 | AO5: =EOMONTH(AN5,3) -> 45838 | AP5: =EOMONTH(AO5,3) -> 45930 | AQ5: =EOMONTH(AP5,3) -> 46022 | AR5: =EOMONTH(AQ5,3) -> 46112 | AS5: =EOMONTH(AR5,3) -> 46203 | AT5: =EOMONTH(AS5,3) -> 46295 | AU5: =EOMONTH(AT5,3) -> 46387 | AV5: =EOMONTH(AU5,3) -> 46477 | ... AX5: =EOMONTH(AW5,3) -> 46660
B7: Paid | D7: =SUM(F7:AL7) -> 840931.24 | F7: =SUMIFS(Invoices!$K$5:$K$2998,Invoices!$D$5:$D$2998,F$5,Invoices!$R$5:$R$2998,1)*(F$5<=$D$2) -> 0 | G7: =SUMIFS(Invoices!$K$5:$K$2998,Invoices!$D$5:$D$2998,G$5,Invoices!$R$5:$R$2998,1)*(G$5<=$D$2) -> 4000 | H7: =SUMIFS(Invoices!$K$5:$K$2998,Invoices!$D$5:$D$2998,H$5,Invoices!$R$5:$R$2998,1)*(H$5<=$D$2) -> 5100 | I7: =SUMIFS(Invoices!$K$5:$K$2998,Invoices!$D$5:$D$2998,I$5,Invoices!$R$5:$R$2998,1)*(I$5<=$D$2) -> 0 | J7: =SUMIFS(Invoices!$K$5:$K$2998,Invoices!$D$5:$D$2998,J$5,Invoices!$R$5:$R$2998,1)*(J$5<=$D$2) -> 64200 | K7: =SUMIFS(Invoices!$K$5:$K$2998,Invoices!$D$5:$D$2998,K$5,Invoices!$R$5:$R$2998,1)*(K$5<=$D$2) -> 173392.79 | L7: =SUMIFS(Invoices!$K$5:$K$2998,Invoices!$D$5:$D$2998,L$5,Invoices!$R$5:$R$2998,1)*(L$5<=$D$2) -> 16000 | M7: =SUMIFS(Invoices!$K$5:$K$2998,Invoices!$D$5:$D$2998,M$5,Invoices!$R$5:$R$2998,1)*(M$5<=$D$2) -> 6802 | ... AL7: =SUMIFS(Invoices!$K$5:$K$2998,Invoices!$D$5:$D$2998,AL$5,Invoices!$R$5:$R$2998,1)*(AL$5<=$D$2) -> 0 | AN7: =-SUMIFS($F7:$AL7,$F$3:$AL$3,AN$3) -> -9100 | AO7: =-SUMIFS($F7:$AL7,$F$3:$AL$3,AO$3) -> -237592.79 | AP7: =-SUMIFS($F7:$AL7,$F$3:$AL$3,AP$3) -> -352507.83 | AQ7: =-SUMIFS($F7:$AL7,$F$3:$AL$3,AQ$3) -> -76408.414 | AR7: =-SUMIFS($F7:$AL7,$F$3:$AL$3,AR$3) -> -165322.21 | AS7: =-SUMIFS($F7:$AL7,$F$3:$AL$3,AS$3) -> 0 | AT7: =-SUMIFS($F7:$AL7,$F$3:$AL$3,AT$3) -> 0 | AU7: =-SUMIFS($F7:$AL7,$F$3:$AL$3,AU$3) -> 0 | ... AX7: =-SUMIFS($F7:$AL7,$F$3:$AL$3,AX$3) -> 0 | AZ7: =SUM(AN7:AX7) -> -840931.24
B8: VAT | D8: =SUM(F8:AL8) -> 182741.1 | F8: =SUMIFS(Invoices!$L$5:$L$2998,Invoices!$D$5:$D$2998,F$5,Invoices!$R$5:$R$2998,1)*(F$5<=$D$2) -> 0 | G8: =SUMIFS(Invoices!$L$5:$L$2998,Invoices!$D$5:$D$2998,G$5,Invoices!$R$5:$R$2998,1)*(G$5<=$D$2) -> 0 | H8: =SUMIFS(Invoices!$L$5:$L$2998,Invoices!$D$5:$D$2998,H$5,Invoices!$R$5:$R$2998,1)*(H$5<=$D$2) -> 572 | I8: =SUMIFS(Invoices!$L$5:$L$2998,Invoices!$D$5:$D$2998,I$5,Invoices!$R$5:$R$2998,1)*(I$5<=$D$2) -> 0 | J8: =SUMIFS(Invoices!$L$5:$L$2998,Invoices!$D$5:$D$2998,J$5,Invoices!$R$5:$R$2998,1)*(J$5<=$D$2) -> 14124 | K8: =SUMIFS(Invoices!$L$5:$L$2998,Invoices!$D$5:$D$2998,K$5,Invoices!$R$5:$R$2998,1)*(K$5<=$D$2) -> 38146.414 | L8: =SUMIFS(Invoices!$L$5:$L$2998,Invoices!$D$5:$D$2998,L$5,Invoices!$R$5:$R$2998,1)*(L$5<=$D$2) -> 3520 | M8: =SUMIFS(Invoices!$L$5:$L$2998,Invoices!$D$5:$D$2998,M$5,Invoices!$R$5:$R$2998,1)*(M$5<=$D$2) -> 0 | ... AL8: =SUMIFS(Invoices!$L$5:$L$2998,Invoices!$D$5:$D$2998,AL$5,Invoices!$R$5:$R$2998,1)*(AL$5<=$D$2) -> 0 | AN8: =-SUMIFS($F8:$AL8,$F$3:$AL$3,AN$3) -> -572 | AO8: =-SUMIFS($F8:$AL8,$F$3:$AL$3,AO$3) -> -52270.414 | AP8: =-SUMIFS($F8:$AL8,$F$3:$AL$3,AP$3) -> -77681.177 | AQ8: =-SUMIFS($F8:$AL8,$F$3:$AL$3,AQ$3) -> -16130.051 | AR8: =-SUMIFS($F8:$AL8,$F$3:$AL$3,AR$3) -> -36087.457 | AS8: =-SUMIFS($F8:$AL8,$F$3:$AL$3,AS$3) -> 0 | AT8: =-SUMIFS($F8:$AL8,$F$3:$AL$3,AT$3) -> 0 | AU8: =-SUMIFS($F8:$AL8,$F$3:$AL$3,AU$3) -> 0 | ... AX8: =-SUMIFS($F8:$AL8,$F$3:$AL$3,AX$3) -> 0 | AZ8: =SUM(AN8:AX8) -> -182741.1
B9: Gross Paid | D9: =SUM(F9:AL9) -> 1023672.3 | F9: =SUM(F7:F8) -> 0 | G9: =SUM(G7:G8) -> 4000 | H9: =SUM(H7:H8) -> 5672 | I9: =SUM(I7:I8) -> 0 | J9: =SUM(J7:J8) -> 78324 | K9: =SUM(K7:K8) -> 211539.2 | L9: =SUM(L7:L8) -> 19520 | M9: =SUM(M7:M8) -> 6802 | ... AL9: =SUM(AL7:AL8) -> 0 | AN9: =SUM(AN7:AN8) -> -9672 | AO9: =SUM(AO7:AO8) -> -289863.2 | AP9: =SUM(AP7:AP8) -> -430189 | AQ9: =SUM(AQ7:AQ8) -> -92538.465 | AR9: =SUM(AR7:AR8) -> -201409.67 | AS9: =SUM(AS7:AS8) -> 0 | AT9: =SUM(AT7:AT8) -> 0 | AU9: =SUM(AU7:AU8) -> 0 | ... AX9: =SUM(AX7:AX8) -> 0 | AZ9: =SUM(AN9:AX9) -> -1023672.3
B12: Artelia Forecast | D12: =SUM(F12:AL12) -> 7343225 | F12: 0 | G12: 0 | H12: 0 | I12: 0 | J12: 0 | K12: 0 | L12: 0 | M12: 0 | N12: 0 | O12: 0 | P12: 0 | Q12: 0 | R12: 0 | S12: 0 | T12: 0 | U12: 598243.08 | V12: 680821.78 | W12: 770821.78 | X12: 766417.33 | Y12: 682774.66 | Z12: 795274.66 | AA12: 810274.66 | AB12: 831274.66 | AC12: 649195.96 | AD12: 758126.4 | AE12: 0 | AF12: 0 | AG12: 0 | AH12: 0 | AI12: 0 | AJ12: 0 | AK12: 0 | AL12: 0
B13: % Total | D13: =SUM(F13:AL13) -> 1 | F13: =IFERROR(F12/$D$12,0) -> 0 | G13: =IFERROR(G12/$D$12,0) -> 0 | H13: =IFERROR(H12/$D$12,0) -> 0 | I13: =IFERROR(I12/$D$12,0) -> 0 | J13: =IFERROR(J12/$D$12,0) -> 0 | K13: =IFERROR(K12/$D$12,0) -> 0 | L13: =IFERROR(L12/$D$12,0) -> 0 | M13: =IFERROR(M12/$D$12,0) -> 0 | ... AL13: =IFERROR(AL12/$D$12,0) -> 0
B14: % Total - Forecast Curve | D14: =SUM(F14:AL14) -> 1 | F14: 0 | G14: 0 | H14: 0 | I14: 0 | J14: 0 | K14: 0 | L14: 0 | M14: 0 | N14: 0 | O14: 0 | P14: 0 | Q14: 0 | R14: 0 | S14: 0 | T14: 0 | U14: =IFERROR(U13/SUM($U$13:$AL$13),0) -> 0.081468712 | V14: =IFERROR(V13/SUM($U$13:$AL$13),0) -> 0.092714275 | W14: =IFERROR(W13/SUM($U$13:$AL$13),0) -> 0.10497047 | X14: =IFERROR(X13/SUM($U$13:$AL$13),0) -> 0.10437067 | Y14: =IFERROR(Y13/SUM($U$13:$AL$13),0) -> 0.092980218 | Z14: =IFERROR(Z13/SUM($U$13:$AL$13),0) -> 0.10830046 | AA14: =IFERROR(AA13/SUM($U$13:$AL$13),0) -> 0.11034316 | AB14: =IFERROR(AB13/SUM($U$13:$AL$13),0) -> 0.11320294 | ... AL14: =IFERROR(AL13/SUM($U$13:$AL$13),0) -> 0
B15: Remaining Spend | D15: =9000000-D7-300000 -> 7859068.8 | F15: =F$14*$D$15 -> 0 | G15: =G$14*$D$15 -> 0 | H15: =H$14*$D$15 -> 0 | I15: =I$14*$D$15 -> 0 | J15: =J$14*$D$15 -> 0 | K15: =K$14*$D$15 -> 0 | L15: =L$14*$D$15 -> 0 | M15: =M$14*$D$15 -> 0 | ... AL15: =AL$14*$D$15 -> 0 | AN15: =-SUMIFS($F15:$AL15,$F$3:$AL$3,AN$3) -> 0 | AO15: =-SUMIFS($F15:$AL15,$F$3:$AL$3,AO$3) -> 0 | AP15: =-SUMIFS($F15:$AL15,$F$3:$AL$3,AP$3) -> 0 | AQ15: =-SUMIFS($F15:$AL15,$F$3:$AL$3,AQ$3) -> 0 | AR15: =-SUMIFS($F15:$AL15,$F$3:$AL$3,AR$3) -> 0 | AS15: =-SUMIFS($F15:$AL15,$F$3:$AL$3,AS$3) -> -2193886.2 | AT15: =-SUMIFS($F15:$AL15,$F$3:$AL$3,AT$3) -> -2402135 | AU15: =-SUMIFS($F15:$AL15,$F$3:$AL$3,AU$3) -> -2451664.6 | ... AX15: =-SUMIFS($F15:$AL15,$F$3:$AL$3,AX$3) -> 0 | AZ15: =SUM(AN15:AX15) -> -7859068.8
B16: VAT (Assumption) | D16: =SUM(F16:AL16) -> 1728995.1 | F16: =F15*22% -> 0 | G16: =G15*22% -> 0 | H16: =H15*22% -> 0 | I16: =I15*22% -> 0 | J16: =J15*22% -> 0 | K16: =K15*22% -> 0 | L16: =L15*22% -> 0 | M16: =M15*22% -> 0 | ... AL16: =AL15*22% -> 0 | AN16: =-SUMIFS($F16:$AL16,$F$3:$AL$3,AN$3) -> 0 | AO16: =-SUMIFS($F16:$AL16,$F$3:$AL$3,AO$3) -> 0 | AP16: =-SUMIFS($F16:$AL16,$F$3:$AL$3,AP$3) -> 0 | AQ16: =-SUMIFS($F16:$AL16,$F$3:$AL$3,AQ$3) -> 0 | AR16: =-SUMIFS($F16:$AL16,$F$3:$AL$3,AR$3) -> 0 | AS16: =-SUMIFS($F16:$AL16,$F$3:$AL$3,AS$3) -> -482654.97 | AT16: =-SUMIFS($F16:$AL16,$F$3:$AL$3,AT$3) -> -528469.7 | AU16: =-SUMIFS($F16:$AL16,$F$3:$AL$3,AU$3) -> -539366.21 | ... AX16: =-SUMIFS($F16:$AL16,$F$3:$AL$3,AX$3) -> 0 | AZ16: =SUM(AN16:AX16) -> -1728995.1
B17: Remaining + VAT | D17: =SUM(F17:AN17) -> 9588063.9 | F17: =SUM(F15,F16) -> 0 | G17: =SUM(G15,G16) -> 0 | H17: =SUM(H15,H16) -> 0 | I17: =SUM(I15,I16) -> 0 | J17: =SUM(J15,J16) -> 0 | K17: =SUM(K15,K16) -> 0 | L17: =SUM(L15,L16) -> 0 | M17: =SUM(M15,M16) -> 0 | ... AL17: =SUM(AL15,AL16) -> 0 | AN17: =SUM(AN15,AN16) -> 0 | AO17: =SUM(AO15,AO16) -> 0 | AP17: =SUM(AP15,AP16) -> 0 | AQ17: =SUM(AQ15,AQ16) -> 0 | AR17: =SUM(AR15,AR16) -> 0 | AS17: =SUM(AS15,AS16) -> -2676541.2 | AT17: =SUM(AT15,AT16) -> -2930604.7 | AU17: =SUM(AU15,AU16) -> -2991030.8 | ... AX17: =SUM(AX15,AX16) -> 0 | AZ17: =SUM(AN17:AX17) -> -9588063.9
B19: Model - Dev Costs | D19: =SUM(F19:AL19) -> 7859068.8 | F19: 0 | G19: 0 | H19: 0 | I19: 0 | J19: 0 | K19: 0 | L19: 0 | M19: 0 | N19: 0 | O19: 0 | P19: 0 | Q19: 0 | R19: 0 | S19: 0 | T19: 0 | U19: =SUM(U7,U15) -> 640268.21 | V19: =SUM(V7,V15) -> 728647.86 | W19: =SUM(W7,W15) -> 824970.14 | X19: =SUM(X7,X15) -> 820256.29 | Y19: =SUM(Y7,Y15) -> 730737.93 | Z19: =SUM(Z7,Z15) -> 851140.78 | AA19: =SUM(AA7,AA15) -> 867194.49 | AB19: =SUM(AB7,AB15) -> 889669.69 | ... AL19: =SUM(AL7,AL15) -> 0 | AN19: 0 | AO19: 0 | AP19: 0 | AQ19: 0 | AR19: 0 | AS19: =SUM(AS7,AS15) -> -2193886.2 | AT19: =SUM(AT7,AT15) -> -2402135 | AU19: =SUM(AU7,AU15) -> -2451664.6 | AV19: =SUM(AV7,AV15) -> -811382.95 | AW19: =SUM(AW7,AW15) -> 0 | AX19: =SUM(AX7,AX15) -> 0 | AZ19: =SUM(AN19:AX19) -> -7859068.8
B20: Model - VAT Due | D20: =SUM(F20:AL20) -> 1728995.1 | F20: 0 | G20: 0 | H20: 0 | I20: 0 | J20: 0 | K20: 0 | L20: 0 | M20: 0 | N20: 0 | O20: 0 | P20: 0 | Q20: 0 | R20: 0 | S20: 0 | T20: 0 | U20: =U16+U8 -> 140859.01 | V20: =V16 -> 160302.53 | W20: =W16 -> 181493.43 | X20: =X16 -> 180456.38 | Y20: =Y16 -> 160762.34 | Z20: =Z16 -> 187250.97 | AA20: =AA16 -> 190782.79 | AB20: =AB16 -> 195727.33 | AC20: =AC16 -> 152856.09 | ... AL20: =AL16 -> 0 | AN20: 0 | AO20: 0 | AP20: 0 | AQ20: 0 | AR20: 0 | AS20: =SUM(AS8,AS16) -> -482654.97 | AT20: =SUM(AT8,AT16) -> -528469.7 | AU20: =SUM(AU8,AU16) -> -539366.21 | AV20: =SUM(AV8,AV16) -> -178504.25 | AW20: =SUM(AW8,AW16) -> 0 | AX20: =SUM(AX8,AX16) -> 0 | AZ20: =SUM(AN20:AX20) -> -1728995.1
B21: Model - VAT Repaid | D21: =SUM(F21:AL21) -> -1728995.1 | F21: 0 | G21: 0 | H21: 0 | I21: 0 | J21: 0 | K21: 0 | L21: 0 | M21: 0 | N21: 0 | O21: 0 | P21: 0 | Q21: 0 | R21: 0 | S21: 0 | T21: 0 | U21: 0 | V21: 0 | W21: 0 | X21: 0 | Y21: 0 | Z21: 0 | AA21: =-U20 -> -140859.01 | AB21: =-V20 -> -160302.53 | AC21: =-W20 -> -181493.43 | AD21: =-X20 -> -180456.38 | AE21: =-Y20 -> -160762.34 | AF21: =-Z20 -> -187250.97 | AG21: =-AA20 -> -190782.79 | AH21: =-AB20 -> -195727.33 | ... AL21: =-AF20 -> 0 | AN21: 0 | AO21: 0 | AP21: 0 | AQ21: 0 | AR21: 0 | AS21: 0 | AT21: 0 | AU21: =-AS20 -> 482654.97 | AV21: =-AT20 -> 528469.7 | AW21: =-AU20 -> 539366.21 | AX21: =-AV20 -> 178504.25 | AZ21: =SUM(AN21:AX21) -> 1728995.1
AN26: =AN7/SUM($AZ$7,$AZ$15) -> 0.001045977 | AO26: =AO7/SUM($AZ$7,$AZ$15) -> 0.027309516 | AP26: =AP7/SUM($AZ$7,$AZ$15) -> 0.040518141 | AQ26: =AQ7/SUM($AZ$7,$AZ$15) -> 0.0087825763 | AR26: =AR7/SUM($AZ$7,$AZ$15) -> 0.019002553 | AS26: =AS15/SUM($AZ$7,$AZ$15) -> 0.25217083 | AT26: =AT15/SUM($AZ$7,$AZ$15) -> 0.27610747 | AU26: =AU15/SUM($AZ$7,$AZ$15) -> 0.28180053 | AV26: =AV15/SUM($AZ$7,$AZ$15) -> 0.093262408

Sheet Model - Preopening & Fees
B2: Florence - Preopening Budget | F2: =SUMIFS(F$11:F$162,$A$11:$A$162,1) -> 1104145 | G2: =SUMIFS(G$11:G$162,$A$11:$A$162,1) -> 307666.22 | H2: =SUMIFS(H$11:H$162,$A$11:$A$162,1) -> 798480.02
B4: Actuals To Date | J4: 46203
B5: Period | L5: 0 | M5: 0 | N5: 0 | O5: =L5+1 -> 1 | P5: =M5+1 -> 1 | Q5: =N5+1 -> 1 | R5: =O5+1 -> 2 | S5: =P5+1 -> 2 | T5: =Q5+1 -> 2 | U5: =R5+1 -> 3 | V5: =S5+1 -> 3 | ... AR5: =AO5+1 -> 10 | AT5: 0 | AU5: =AT5+1 -> 1 | AV5: =AU5+1 -> 2 | AW5: =AV5+1 -> 3 | AX5: =AW5+1 -> 4 | AY5: =AX5+1 -> 5 | AZ5: =AY5+1 -> 6 | BA5: =AZ5+1 -> 7 | BB5: =BA5+1 -> 8 | ... BD5: =BC5+1 -> 10
B6: BoP | L6: 45658 | M6: =L7+1 -> 45689 | N6: =M7+1 -> 45717 | O6: =N7+1 -> 45748 | P6: =O7+1 -> 45778 | Q6: =P7+1 -> 45809 | R6: =Q7+1 -> 45839 | S6: =R7+1 -> 45870 | T6: =S7+1 -> 45901 | ... AR6: =AQ7+1 -> 46631 | AT6: 45658 | AU6: =AT7+1 -> 45748 | AV6: =AU7+1 -> 45839 | AW6: =AV7+1 -> 45931 | AX6: =AW7+1 -> 46023 | AY6: =AX7+1 -> 46113 | AZ6: =AY7+1 -> 46204 | BA6: =AZ7+1 -> 46296 | BB6: =BA7+1 -> 46388 | ... BD6: =BC7+1 -> 46569
B7: EoP | J7: Total | L7: 45688 | M7: =EOMONTH(L7,1) -> 45716 | N7: =EOMONTH(M7,1) -> 45747 | O7: =EOMONTH(N7,1) -> 45777 | P7: =EOMONTH(O7,1) -> 45808 | Q7: =EOMONTH(P7,1) -> 45838 | R7: =EOMONTH(Q7,1) -> 45869 | S7: =EOMONTH(R7,1) -> 45900 | T7: =EOMONTH(S7,1) -> 45930 | ... AR7: =EOMONTH(AQ7,1) -> 46660 | AT7: 45747 | AU7: =EOMONTH(AT7,3) -> 45838 | AV7: =EOMONTH(AU7,3) -> 45930 | AW7: =EOMONTH(AV7,3) -> 46022 | AX7: =EOMONTH(AW7,3) -> 46112 | AY7: =EOMONTH(AX7,3) -> 46203 | AZ7: =EOMONTH(AY7,3) -> 46295 | BA7: =EOMONTH(AZ7,3) -> 46387 | BB7: =EOMONTH(BA7,3) -> 46477 | ... BD7: =EOMONTH(BC7,3) -> 46660
B9: Marketing
B11: Budget | C11: Description | D11: Bucket | E11: Owner | F11: Budget | G11: Spent | H11: Remaining
B13: PR & Communications
A14: 1 | B14: Communication Plan (with Local Agency) | D14: Marketing | E14: Aniek | F14: 20000 | G14: =SUMIFS($L14:$AR14,$L$7:$AR$7,"<="&$J$4) -> 0 | H14: =J14-G14 -> 20000 | J14: =SUM(L14:AR14) -> 20000 | L14: =SUMIFS('Invoices - Preopening'!$I$20:$I$299,'Invoices - Preopening'!$H$20:$H$299,">="&L$6,'Invoices - Preopening'!$H$20:$H$299,"<="&L$7,'Invoices - Preopening'!$C$20:$C$299,'Model - Preopening & Fees'!$B14) -> 0 | M14: =SUMIFS('Invoices - Preopening'!$I$20:$I$299,'Invoices - Preopening'!$H$20:$H$299,">="&M$6,'Invoices - Preopening'!$H$20:$H$299,"<="&M$7,'Invoices - Preopening'!$C$20:$C$299,'Model - Preopening & Fees'!$B14) -> 0 | N14: =SUMIFS('Invoices - Preopening'!$I$20:$I$299,'Invoices - Preopening'!$H$20:$H$299,">="&N$6,'Invoices - Preopening'!$H$20:$H$299,"<="&N$7,'Invoices - Preopening'!$C$20:$C$299,'Model - Preopening & Fees'!$B14) -> 0 | O14: =SUMIFS('Invoices - Preopening'!$I$20:$I$299,'Invoices - Preopening'!$H$20:$H$299,">="&O$6,'Invoices - Preopening'!$H$20:$H$299,"<="&O$7,'Invoices - Preopening'!$C$20:$C$299,'Model - Preopening & Fees'!$B14) -> 0 | P14: =SUMIFS('Invoices - Preopening'!$I$20:$I$299,'Invoices - Preopening'!$H$20:$H$299,">="&P$6,'Invoices - Preopening'!$H$20:$H$299,"<="&P$7,'Invoices - Preopening'!$C$20:$C$299,'Model - Preopening & Fees'!$B14) -> 0 | Q14: =SUMIFS('Invoices - Preopening'!$I$20:$I$299,'Invoices - Preopening'!$H$20:$H$299,">="&Q$6,'Invoices - Preopening'!$H$20:$H$299,"<="&Q$7,'Invoices - Preopening'!$C$20:$C$299,'Model - Preopening & Fees'!$B14) -> 0 | R14: =SUMIFS('Invoices - Preopening'!$I$20:$I$299,'Invoices - Preopening'!$H$20:$H$299,">="&R$6,'Invoices - Preopening'!$H$20:$H$299,"<="&R$7,'Invoices - Preopening'!$C$20:$C$299,'Model - Preopening & Fees'!$B14) -> 0 | S14: =SUMIFS('Invoices - Preopening'!$I$20:$I$299,'Invoices - Preopening'!$H$20:$H$299,">="&S$6,'Invoices - Preopening'!$H$20:$H$299,"<="&S$7,'Invoices - Preopening'!$C$20:$C$299,'Model - Preopening & Fees'!$B14) -> 0 | ... AC14: =SUMIFS('Invoices - Preopening'!$I$20:$I$299,'Invoices - Preopening'!$H$20:$H$299,">="&AC$6,'Invoices - Preopening'!$H$20:$H$299,"<="&AC$7,'Invoices - Preopening'!$C$20:$C$299,'Model - Preopening & Fees'!$B14) -> 0 | AD14: 20000 | AE14: 0 | AF14: 0 | AG14: 0 | AH14: 0 | AI14: 0 | AJ14: 0 | AK14: 0 | AL14: 0 | AM14: 0 | AN14: 0 | AO14: 0 | AP14: 0 | AQ14: 0 | AR14: 0 | AT14: =-SUMIFS($L14:$AR14,$L$5:$AR$5,AT$5) -> 0 | AU14: =-SUMIFS($L14:$AR14,$L$5:$AR$5,AU$5) -> 0 | AV14: =-SUMIFS($L14:$AR14,$L$5:$AR$5,AV$5) -> 0 | AW14: =-SUMIFS($L14:$AR14,$L$5:$AR$5,AW$5) -> 0 | AX14: =-SUMIFS($L14:$AR14,$L$5:$AR$5,AX$5) -> 0 | AY14: =-SUMIFS($L14:$AR14,$L$5:$AR$5,AY$5) -> 0 | AZ14: =-SUMIFS($L14:$AR14,$L$5:$AR$5,AZ$5) -> -20000 | BA14: =-SUMIFS($L14:$AR14,$L$5:$AR$5,BA$5) -> 0 | ... BD14: =-SUMIFS($L14:$AR14,$L$5:$AR$5,BD$5) -> 0 | BF14: =SUM(AT14:BD14) -> -20000
A15: 1 | B15: PR (with Local Agency) year retainer | D15: Marketing | E15: Aniek | F15: 26500 | G15: =SUMIFS($L15:$AR15,$L$7:$AR$7,"<="&$J$4) -> 0 | H15: =J15-G15 -> 14000 | J15: =SUM(L15:AR15) -> 14000 | L15: =SUMIFS('Invoices - Preopening'!$I$20:$I$299,'Invoices - Preopening'!$H$20:$H$299,">="&L$6,'Invoices - Preopening'!$H$20:$H$299,"<="&L$7,'Invoices - Preopening'!$C$20:$C$299,'Model - Preopening & Fees'!$B15) -> 0 | M15: =SUMIFS('Invoices - Preopening'!$I$20:$I$299,'Invoices - Preopening'!$H$20:$H$299,">="&M$6,'Invoices - Preopening'!$H$20:$H$299,"<="&M$7,'Invoices - Preopening'!$C$20:$C$299,'Model - Preopening & Fees'!$B15) -> 0 | N15: =SUMIFS('Invoices - Preopening'!$I$20:$I$299,'Invoices - Preopening'!$H$20:$H$299,">="&N$6,'Invoices - Preopening'!$H$20:$H$299,"<="&N$7,'Invoices - Preopening'!$C$20:$C$299,'Model - Preopening & Fees'!$B15) -> 0 | O15: =SUMIFS('Invoices - Preopening'!$I$20:$I$299,'Invoices - Preopening'!$H$20:$H$299,">="&O$6,'Invoices - Preopening'!$H$20:$H$299,"<="&O$7,'Invoices - Preopening'!$C$20:$C$299,'Model - Preopening & Fees'!$B15) -> 0 | P15: =SUMIFS('Invoices - Preopening'!$I$20:$I$299,'Invoices - Preopening'!$H$20:$H$299,">="&P$6,'Invoices - Preopening'!$H$20:$H$299,"<="&P$7,'Invoices - Preopening'!$C$20:$C$299,'Model - Preopening & Fees'!$B15) -> 0 | Q15: =SUMIFS('Invoices - Preopening'!$I$20:$I$299,'Invoices - Preopening'!$H$20:$H$299,">="&Q$6,'Invoices - Preopening'!$H$20:$H$299,"<="&Q$7,'Invoices - Preopening'!$C$20:$C$299,'Model - Preopening & Fees'!$B15) -> 0 | R15: =SUMIFS('Invoices - Preopening'!$I$20:$I$299,'Invoices - Preopening'!$H$20:$H$299,">="&R$6,'Invoices - Preopening'!$H$20:$H$299,"<="&R$7,'Invoices - Preopening'!$C$20:$C$299,'Model - Preopening & Fees'!$B15) -> 0 | S15: =SUMIFS('Invoices - Preopening'!$I$20:$I$299,'Invoices - Preopening'!$H$20:$H$299,">="&S$6,'Invoices - Preopening'!$H$20:$H$299,"<="&S$7,'Invoices - Preopening'!$C$20:$C$299,'Model - Preopening & Fees'!$B15) -> 0 | ... AC15: =SUMIFS('Invoices - Preopening'!$I$20:$I$299,'Invoices - Preopening'!$H$20:$H$299,">="&AC$6,'Invoices - Preopening'!$H$20:$H$299,"<="&AC$7,'Invoices - Preopening'!$C$20:$C$299,'Model - Preopening & Fees'!$B15) -> 0 | AD15: 0 | AE15: 2000 | AF15: 2000 | AG15: 2000 | AH15: 2000 | AI15: 2000 | AJ15: 2000 | AK15: 2000 | AL15: 0 | AM15: 0 | AN15: 0 | AO15: 0 | AP15: 0 | AQ15: 0 | AR15: 0 | AT15: =-SUMIFS($L15:$AR15,$L$5:$AR$5,AT$5) -> 0 | AU15: =-SUMIFS($L15:$AR15,$L$5:$AR$5,AU$5) -> 0 | AV15: =-SUMIFS($L15:$AR15,$L$5:$AR$5,AV$5) -> 0 | AW15: =-SUMIFS($L15:$AR15,$L$5:$AR$5,AW$5) -> 0 | AX15: =-SUMIFS($L15:$AR15,$L$5:$AR$5,AX$5) -> 0 | AY15: =-SUMIFS($L15:$AR15,$L$5:$AR$5,AY$5) -> 0 | AZ15: =-SUMIFS($L15:$AR15,$L$5:$AR$5,AZ$5) -> -4000 | BA15: =-SUMIFS($L15:$AR15,$L$5:$AR$5,BA$5) -> -6000 | ... BD15: =-SUMIFS($L15:$AR15,$L$5:$AR$5,BD$5) -> 0 | BF15: =SUM(AT15:BD15) -> -14000
B17: Photo & Video
A18: 1 | B18: Photoshoot September - Mock Up Rooms | D18: Marketing | E18: Aniek | F18: 3000 | G18: =SUMIFS($L18:$AR18,$L$7:$AR$7,"<="&$J$4) -> 1000 | H18: =J18-G18 -> 2000 | J18: =SUM(L18:AR18) -> 3000 | L18: =SUMIFS('Invoices - Preopening'!$I$20:$I$299,'Invoices - Preopening'!$H$20:$H$299,">="&L$6,'Invoices - Preopening'!$H$20:$H$299,"<="&L$7,'Invoices - Preopening'!$C$20:$C$299,'Model - Preopening & Fees'!$B18) -> 0 | M18: =SUMIFS('Invoices - Preopening'!$I$20:$I$299,'Invoices - Preopening'!$H$20:$H$299,">="&M$6,'Invoices - Preopening'!$H$20:$H$299,"<="&M$7,'Invoices - Preopening'!$C$20:$C$299,'Model - Preopening & Fees'!$B18) -> 0 | N18: =SUMIFS('Invoices - Preopening'!$I$20:$I$299,'Invoices - Preopening'!$H$20:$H$299,">="&N$6,'Invoices - Preopening'!$H$20:$H$299,"<="&N$7,'Invoices - Preopening'!$C$20:$C$299,'Model - Preopening & Fees'!$B18) -> 0 | O18: =SUMIFS('Invoices - Preopening'!$I$20:$I$299,'Invoices - Preopening'!$H$20:$H$299,">="&O$6,'Invoices - Preopening'!$H$20:$H$299,"<="&O$7,'Invoices - Preopening'!$C$20:$C$299,'Model - Preopening & Fees'!$B18) -> 0 | P18: =SUMIFS('Invoices - Preopening'!$I$20:$I$299,'Invoices - Preopening'!$H$20:$H$299,">="&P$6,'Invoices - Preopening'!$H$20:$H$299,"<="&P$7,'Invoices - Preopening'!$C$20:$C$299,'Model - Preopening & Fees'!$B18) -> 0 | Q18: =SUMIFS('Invoices - Preopening'!$I$20:$I$299,'Invoices - Preopening'!$H$20:$H$299,">="&Q$6,'Invoices - Preopening'!$H$20:$H$299,"<="&Q$7,'Invoices - Preopening'!$C$20:$C$299,'Model - Preopening & Fees'!$B18) -> 0 | R18: =SUMIFS('Invoices - Preopening'!$I$20:$I$299,'Invoices - Preopening'!$H$20:$H$299,">="&R$6,'Invoices - Preopening'!$H$20:$H$299,"<="&R$7,'Invoices - Preopening'!$C$20:$C$299,'Model - Preopening & Fees'!$B18) -> 0 | S18: =SUMIFS('Invoices - Preopening'!$I$20:$I$299,'Invoices - Preopening'!$H$20:$H$299,">="&S$6,'Invoices - Preopening'!$H$20:$H$299,"<="&S$7,'Invoices - Preopening'!$C$20:$C$299,'Model - Preopening & Fees'!$B18) -> 0 | ... AC18: =SUMIFS('Invoices - Preopening'!$I$20:$I$299,'Invoices - Preopening'!$H$20:$H$299,">="&AC$6,'Invoices - Preopening'!$H$20:$H$299,"<="&AC$7,'Invoices - Preopening'!$C$20:$C$299,'Model - Preopening & Fees'!$B18) -> 0 | AD18: 0 | AE18: 0 | AF18: 2000 | AG18: 0 | AH18: 0 | AI18: 0 | AJ18: 0 | AK18: 0 | AL18: 0 | AM18: 0 | AN18: 0 | AO18: 0 | AP18: 0 | AQ18: 0 | AR18: 0 | AT18: =-SUMIFS($L18:$AR18,$L$5:$AR$5,AT$5) -> 0 | AU18: =-SUMIFS($L18:$AR18,$L$5:$AR$5,AU$5) -> 0 | AV18: =-SUMIFS($L18:$AR18,$L$5:$AR$5,AV$5) -> 0 | AW18: =-SUMIFS($L18:$AR18,$L$5:$AR$5,AW$5) -> -1000 | AX18: =-SUMIFS($L18:$AR18,$L$5:$AR$5,AX$5) -> 0 | AY18: =-SUMIFS($L18:$AR18,$L$5:$AR$5,AY$5) -> 0 | AZ18: =-SUMIFS($L18:$AR18,$L$5:$AR$5,AZ$5) -> -2000 | BA18: =-SUMIFS($L18:$AR18,$L$5:$AR$5,BA$5) -> 0 | ... BD18: =-SUMIFS($L18:$AR18,$L$5:$AR$5,BD$5) -> 0 | BF18: =SUM(AT18:BD18) -> -3000
A19: 1 | B19: Photoshoot Full February | D19: Marketing | E19: Aniek | F19: 4000 | G19: =SUMIFS($L19:$AR19,$L$7:$AR$7,"<="&$J$4) -> 0 | H19: =J19-G19 -> 4000 | J19: =SUM(L19:AR19) -> 4000 | L19: =SUMIFS('Invoices - Preopening'!$I$20:$I$299,'Invoices - Preopening'!$H$20:$H$299,">="&L$6,'Invoices - Preopening'!$H$20:$H$299,"<="&L$7,'Invoices - Preopening'!$C$20:$C$299,'Model - Preopening & Fees'!$B19) -> 0 | M19: =SUMIFS('Invoices - Preopening'!$I$20:$I$299,'Invoices - Preopening'!$H$20:$H$299,">="&M$6,'Invoices - Preopening'!$H$20:$H$299,"<="&M$7,'Invoices - Preopening'!$C$20:$C$299,'Model - Preopening & Fees'!$B19) -> 0 | N19: =SUMIFS('Invoices - Preopening'!$I$20:$I$299,'Invoices - Preopening'!$H$20:$H$299,">="&N$6,'Invoices - Preopening'!$H$20:$H$299,"<="&N$7,'Invoices - Preopening'!$C$20:$C$299,'Model - Preopening & Fees'!$B19) -> 0 | O19: =SUMIFS('Invoices - Preopening'!$I$20:$I$299,'Invoices - Preopening'!$H$20:$H$299,">="&O$6,'Invoices - Preopening'!$H$20:$H$299,"<="&O$7,'Invoices - Preopening'!$C$20:$C$299,'Model - Preopening & Fees'!$B19) -> 0 | P19: =SUMIFS('Invoices - Preopening'!$I$20:$I$299,'Invoices - Preopening'!$H$20:$H$299,">="&P$6,'Invoices - Preopening'!$H$20:$H$299,"<="&P$7,'Invoices - Preopening'!$C$20:$C$299,'Model - Preopening & Fees'!$B19) -> 0 | Q19: =SUMIFS('Invoices - Preopening'!$I$20:$I$299,'Invoices - Preopening'!$H$20:$H$299,">="&Q$6,'Invoices - Preopening'!$H$20:$H$299,"<="&Q$7,'Invoices - Preopening'!$C$20:$C$299,'Model - Preopening & Fees'!$B19) -> 0 | R19: =SUMIFS('Invoices - Preopening'!$I$20:$I$299,'Invoices - Preopening'!$H$20:$H$299,">="&R$6,'Invoices - Preopening'!$H$20:$H$299,"<="&R$7,'Invoices - Preopening'!$C$20:$C$299,'Model - Preopening & Fees'!$B19) -> 0 | S19: =SUMIFS('Invoices - Preopening'!$I$20:$I$299,'Invoices - Preopening'!$H$20:$H$299,">="&S$6,'Invoices - Preopening'!$H$20:$H$299,"<="&S$7,'Invoices - Preopening'!$C$20:$C$299,'Model - Preopening & Fees'!$B19) -> 0 | ... AC19: =SUMIFS('Invoices - Preopening'!$I$20:$I$299,'Invoices - Preopening'!$H$20:$H$299,">="&AC$6,'Invoices - Preopening'!$H$20:$H$299,"<="&AC$7,'Invoices - Preopening'!$C$20:$C$299,'Model - Preopening & Fees'!$B19) -> 0 | AD19: 0 | AE19: 0 | AF19: 0 | AG19: 0 | AH19: 0 | AI19: 0 | AJ19: 0 | AK19: 4000 | AL19: 0 | AM19: 0 | AN19: 0 | AO19: 0 | AP19: 0 | AQ19: 0 | AR19: 0 | AT19: =-SUMIFS($L19:$AR19,$L$5:$AR$5,AT$5) -> 0 | AU19: =-SUMIFS($L19:$AR19,$L$5:$AR$5,AU$5) -> 0 | AV19: =-SUMIFS($L19:$AR19,$L$5:$AR$5,AV$5) -> 0 | AW19: =-SUMIFS($L19:$AR19,$L$5:$AR$5,AW$5) -> 0 | AX19: =-SUMIFS($L19:$AR19,$L$5:$AR$5,AX$5) -> 0 | AY19: =-SUMIFS($L19:$AR19,$L$5:$AR$5,AY$5) -> 0 | AZ19: =-SUMIFS($L19:$AR19,$L$5:$AR$5,AZ$5) -> 0 | BA19: =-SUMIFS($L19:$AR19,$L$5:$AR$5,BA$5) -> 0 | ... BD19: =-SUMIFS($L19:$AR19,$L$5:$AR$5,BD$5) -> 0 | BF19: =SUM(AT19:BD19) -> -4000
B20: Videoshoot (included in Diginauts scope) | D20: Marketing | E20: Aniek | F20: 0 | G20: =SUMIFS($L20:$AR20,$L$7:$AR$7,"<="&$J$4) -> 0 | H20: =J20-G20 -> 0 | J20: =SUM(L20:AR20) -> 0 | L20: =SUMIFS('Invoices - Preopening'!$I$20:$I$299,'Invoices - Preopening'!$H$20:$H$299,">="&L$6,'Invoices - Preopening'!$H$20:$H$299,"<="&L$7,'Invoices - Preopening'!$C$20:$C$299,'Model - Preopening & Fees'!$B20) -> 0 | M20: =SUMIFS('Invoices - Preopening'!$I$20:$I$299,'Invoices - Preopening'!$H$20:$H$299,">="&M$6,'Invoices - Preopening'!$H$20:$H$299,"<="&M$7,'Invoices - Preopening'!$C$20:$C$299,'Model - Preopening & Fees'!$B20) -> 0 | N20: =SUMIFS('Invoices - Preopening'!$I$20:$I$299,'Invoices - Preopening'!$H$20:$H$299,">="&N$6,'Invoices - Preopening'!$H$20:$H$299,"<="&N$7,'Invoices - Preopening'!$C$20:$C$299,'Model - Preopening & Fees'!$B20) -> 0 | O20: =SUMIFS('Invoices - Preopening'!$I$20:$I$299,'Invoices - Preopening'!$H$20:$H$299,">="&O$6,'Invoices - Preopening'!$H$20:$H$299,"<="&O$7,'Invoices - Preopening'!$C$20:$C$299,'Model - Preopening & Fees'!$B20) -> 0 | P20: =SUMIFS('Invoices - Preopening'!$I$20:$I$299,'Invoices - Preopening'!$H$20:$H$299,">="&P$6,'Invoices - Preopening'!$H$20:$H$299,"<="&P$7,'Invoices - Preopening'!$C$20:$C$299,'Model - Preopening & Fees'!$B20) -> 0 | Q20: =SUMIFS('Invoices - Preopening'!$I$20:$I$299,'Invoices - Preopening'!$H$20:$H$299,">="&Q$6,'Invoices - Preopening'!$H$20:$H$299,"<="&Q$7,'Invoices - Preopening'!$C$20:$C$299,'Model - Preopening & Fees'!$B20) -> 0 | R20: =SUMIFS('Invoices - Preopening'!$I$20:$I$299,'Invoices - Preopening'!$H$20:$H$299,">="&R$6,'Invoices - Preopening'!$H$20:$H$299,"<="&R$7,'Invoices - Preopening'!$C$20:$C$299,'Model - Preopening & Fees'!$B20) -> 0 | S20: =SUMIFS('Invoices - Preopening'!$I$20:$I$299,'Invoices - Preopening'!$H$20:$H$299,">="&S$6,'Invoices - Preopening'!$H$20:$H$299,"<="&S$7,'Invoices - Preopening'!$C$20:$C$299,'Model - Preopening & Fees'!$B20) -> 0 | ... AC20: =SUMIFS('Invoices - Preopening'!$I$20:$I$299,'Invoices - Preopening'!$H$20:$H$299,">="&AC$6,'Invoices - Preopening'!$H$20:$H$299,"<="&AC$7,'Invoices - Preopening'!$C$20:$C$299,'Model - Preopening & Fees'!$B20) -> 0 | AD20: 0 | AE20: 0 | AF20: 0 | AG20: 0 | AH20: 0 | AI20: 0 | AJ20: 0 | AK20: 0 | AL20: 0 | AM20: 0 | AN20: 0 | AO20: 0 | AP20: 0 | AQ20: 0 | AR20: 0
A21: 1 | B21: Videoshoot Lifestyle February | D21: Marketing | E21: Aniek | F21: 4000 | G21: =SUMIFS($L21:$AR21,$L$7:$AR$7,"<="&$J$4) -> 0 | H21: =J21-G21 -> 4000 | J21: =SUM(L21:AR21) -> 4000 | L21: =SUMIFS('Invoices - Preopening'!$I$20:$I$299,'Invoices - Preopening'!$H$20:$H$299,">="&L$6,'Invoices - Preopening'!$H$20:$H$299,"<="&L$7,'Invoices - Preopening'!$C$20:$C$299,'Model - Preopening & Fees'!$B21) -> 0 | M21: =SUMIFS('Invoices - Preopening'!$I$20:$I$299,'Invoices - Preopening'!$H$20:$H$299,">="&M$6,'Invoices - Preopening'!$H$20:$H$299,"<="&M$7,'Invoices - Preopening'!$C$20:$C$299,'Model - Preopening & Fees'!$B21) -> 0 | N21: =SUMIFS('Invoices - Preopening'!$I$20:$I$299,'Invoices - Preopening'!$H$20:$H$299,">="&N$6,'Invoices - Preopening'!$H$20:$H$299,"<="&N$7,'Invoices - Preopening'!$C$20:$C$299,'Model - Preopening & Fees'!$B21) -> 0 | O21: =SUMIFS('Invoices - Preopening'!$I$20:$I$299,'Invoices - Preopening'!$H$20:$H$299,">="&O$6,'Invoices - Preopening'!$H$20:$H$299,"<="&O$7,'Invoices - Preopening'!$C$20:$C$299,'Model - Preopening & Fees'!$B21) -> 0 | P21: =SUMIFS('Invoices - Preopening'!$I$20:$I$299,'Invoices - Preopening'!$H$20:$H$299,">="&P$6,'Invoices - Preopening'!$H$20:$H$299,"<="&P$7,'Invoices - Preopening'!$C$20:$C$299,'Model - Preopening & Fees'!$B21) -> 0 | Q21: =SUMIFS('Invoices - Preopening'!$I$20:$I$299,'Invoices - Preopening'!$H$20:$H$299,">="&Q$6,'Invoices - Preopening'!$H$20:$H$299,"<="&Q$7,'Invoices - Preopening'!$C$20:$C$299,'Model - Preopening & Fees'!$B21) -> 0 | R21: =SUMIFS('Invoices - Preopening'!$I$20:$I$299,'Invoices - Preopening'!$H$20:$H$299,">="&R$6,'Invoices - Preopening'!$H$20:$H$299,"<="&R$7,'Invoices - Preopening'!$C$20:$C$299,'Model - Preopening & Fees'!$B21) -> 0 | S21: =SUMIFS('Invoices - Preopening'!$I$20:$I$299,'Invoices - Preopening'!$H$20:$H$299,">="&S$6,'Invoices - Preopening'!$H$20:$H$299,"<="&S$7,'Invoices - Preopening'!$C$20:$C$299,'Model - Preopening & Fees'!$B21) -> 0 | ... AC21: =SUMIFS('Invoices - Preopening'!$I$20:$I$299,'Invoices - Preopening'!$H$20:$H$299,">="&AC$6,'Invoices - Preopening'!$H$20:$H$299,"<="&AC$7,'Invoices - Preopening'!$C$20:$C$299,'Model - Preopening & Fees'!$B21) -> 0 | AD21: 0 | AE21: 0 | AF21: 0 | AG21: 0 | AH21: 0 | AI21: 0 | AJ21: 0 | AK21: 4000 | AL21: 0 | AM21: 0 | AN21: 0 | AO21: 0 | AP21: 0 | AQ21: 0 | AR21: 0
A22: 1 | B22: Photoshoot Lifestyle & City February | D22: Marketing | E22: Aniek | F22: 4000 | G22: =SUMIFS($L22:$AR22,$L$7:$AR$7,"<="&$J$4) -> 0 | H22: =J22-G22 -> 4000 | J22: =SUM(L22:AR22) -> 4000 | L22: =SUMIFS('Invoices - Preopening'!$I$20:$I$299,'Invoices - Preopening'!$H$20:$H$299,">="&L$6,'Invoices - Preopening'!$H$20:$H$299,"<="&L$7,'Invoices - Preopening'!$C$20:$C$299,'Model - Preopening & Fees'!$B22) -> 0 | M22: =SUMIFS('Invoices - Preopening'!$I$20:$I$299,'Invoices - Preopening'!$H$20:$H$299,">="&M$6,'Invoices - Preopening'!$H$20:$H$299,"<="&M$7,'Invoices - Preopening'!$C$20:$C$299,'Model - Preopening & Fees'!$B22) -> 0 | N22: =SUMIFS('Invoices - Preopening'!$I$20:$I$299,'Invoices - Preopening'!$H$20:$H$299,">="&N$6,'Invoices - Preopening'!$H$20:$H$299,"<="&N$7,'Invoices - Preopening'!$C$20:$C$299,'Model - Preopening & Fees'!$B22) -> 0 | O22: =SUMIFS('Invoices - Preopening'!$I$20:$I$299,'Invoices - Preopening'!$H$20:$H$299,">="&O$6,'Invoices - Preopening'!$H$20:$H$299,"<="&O$7,'Invoices - Preopening'!$C$20:$C$299,'Model - Preopening & Fees'!$B22) -> 0 | P22: =SUMIFS('Invoices - Preopening'!$I$20:$I$299,'Invoices - Preopening'!$H$20:$H$299,">="&P$6,'Invoices - Preopening'!$H$20:$H$299,"<="&P$7,'Invoices - Preopening'!$C$20:$C$299,'Model - Preopening & Fees'!$B22) -> 0 | Q22: =SUMIFS('Invoices - Preopening'!$I$20:$I$299,'Invoices - Preopening'!$H$20:$H$299,">="&Q$6,'Invoices - Preopening'!$H$20:$H$299,"<="&Q$7,'Invoices - Preopening'!$C$20:$C$299,'Model - Preopening & Fees'!$B22) -> 0 | R22: =SUMIFS('Invoices - Preopening'!$I$20:$I$299,'Invoices - Preopening'!$H$20:$H$299,">="&R$6,'Invoices - Preopening'!$H$20:$H$299,"<="&R$7,'Invoices - Preopening'!$C$20:$C$299,'Model - Preopening & Fees'!$B22) -> 0 | S22: =SUMIFS('Invoices - Preopening'!$I$20:$I$299,'Invoices - Preopening'!$H$20:$H$299,">="&S$6,'Invoices - Preopening'!$H$20:$H$299,"<="&S$7,'Invoices - Preopening'!$C$20:$C$299,'Model - Preopening & Fees'!$B22) -> 0 | ... AC22: =SUMIFS('Invoices - Preopening'!$I$20:$I$299,'Invoices - Preopening'!$H$20:$H$299,">="&AC$6,'Invoices - Preopening'!$H$20:$H$299,"<="&AC$7,'Invoices - Preopening'!$C$20:$C$299,'Model - Preopening & Fees'!$B22) -> 0 | AD22: 0 | AE22: 0 | AF22: 0 | AG22: 0 | AH22: 0 | AI22: 0 | AJ22: 0 | AK22: 4000 | AL22: 0 | AM22: 0 | AN22: 0 | AO22: 0 | AP22: 0 | AQ22: 0 | AR22: 0
B24: F&B - Il Solito Branding
A25: 1 | B25: Visual Identity Development (Logo, Fonts, Guidelines) | D25: Marketing | E25: Aniek | F25: 15000 | G25: =SUMIFS($L25:$AR25,$L$7:$AR$7,"<="&$J$4) -> 0 | H25: =J25-G25 -> 15000 | J25: =SUM(L25:AR25) -> 15000 | L25: =SUMIFS('Invoices - Preopening'!$I$20:$I$299,'Invoices - Preopening'!$H$20:$H$299,">="&L$6,'Invoices - Preopening'!$H$20:$H$299,"<="&L$7,'Invoices - Preopening'!$C$20:$C$299,'Model - Preopening & Fees'!$B25) -> 0 | M25: =SUMIFS('Invoices - Preopening'!$I$20:$I$299,'Invoices - Preopening'!$H$20:$H$299,">="&M$6,'Invoices - Preopening'!$H$20:$H$299,"<="&M$7,'Invoices - Preopening'!$C$20:$C$299,'Model - Preopening & Fees'!$B25) -> 0 | N25: =SUMIFS('Invoices - Preopening'!$I$20:$I$299,'Invoices - Preopening'!$H$20:$H$299,">="&N$6,'Invoices - Preopening'!$H$20:$H$299,"<="&N$7,'Invoices - Preopening'!$C$20:$C$299,'Model - Preopening & Fees'!$B25) -> 0 | O25: =SUMIFS('Invoices - Preopening'!$I$20:$I$299,'Invoices - Preopening'!$H$20:$H$299,">="&O$6,'Invoices - Preopening'!$H$20:$H$299,"<="&O$7,'Invoices - Preopening'!$C$20:$C$299,'Model - Preopening & Fees'!$B25) -> 0 | P25: =SUMIFS('Invoices - Preopening'!$I$20:$I$299,'Invoices - Preopening'!$H$20:$H$299,">="&P$6,'Invoices - Preopening'!$H$20:$H$299,"<="&P$7,'Invoices - Preopening'!$C$20:$C$299,'Model - Preopening & Fees'!$B25) -> 0 | Q25: =SUMIFS('Invoices - Preopening'!$I$20:$I$299,'Invoices - Preopening'!$H$20:$H$299,">="&Q$6,'Invoices - Preopening'!$H$20:$H$299,"<="&Q$7,'Invoices - Preopening'!$C$20:$C$299,'Model - Preopening & Fees'!$B25) -> 0 | R25: =SUMIFS('Invoices - Preopening'!$I$20:$I$299,'Invoices - Preopening'!$H$20:$H$299,">="&R$6,'Invoices - Preopening'!$H$20:$H$299,"<="&R$7,'Invoices - Preopening'!$C$20:$C$299,'Model - Preopening & Fees'!$B25) -> 0 | S25: =SUMIFS('Invoices - Preopening'!$I$20:$I$299,'Invoices - Preopening'!$H$20:$H$299,">="&S$6,'Invoices - Preopening'!$H$20:$H$299,"<="&S$7,'Invoices - Preopening'!$C$20:$C$299,'Model - Preopening & Fees'!$B25) -> 0 | ... AC25: =SUMIFS('Invoices - Preopening'!$I$20:$I$299,'Invoices - Preopening'!$H$20:$H$299,">="&AC$6,'Invoices - Preopening'!$H$20:$H$299,"<="&AC$7,'Invoices - Preopening'!$C$20:$C$299,'Model - Preopening & Fees'!$B25) -> 0 | AD25: 7500 | AE25: 7500 | AF25: 0 | AG25: 0 | AH25: 0 | AI25: 0 | AJ25: 0 | AK25: 0 | AL25: 0 | AM25: 0 | AN25: 0 | AO25: 0 | AP25: 0 | AQ25: 0 | AR25: 0 | AT25: =-SUMIFS($L25:$AR25,$L$5:$AR$5,AT$5) -> 0 | AU25: =-SUMIFS($L25:$AR25,$L$5:$AR$5,AU$5) -> 0 | AV25: =-SUMIFS($L25:$AR25,$L$5:$AR$5,AV$5) -> 0 | AW25: =-SUMIFS($L25:$AR25,$L$5:$AR$5,AW$5) -> 0 | AX25: =-SUMIFS($L25:$AR25,$L$5:$AR$5,AX$5) -> 0 | AY25: =-SUMIFS($L25:$AR25,$L$5:$AR$5,AY$5) -> 0 | AZ25: =-SUMIFS($L25:$AR25,$L$5:$AR$5,AZ$5) -> -15000 | BA25: =-SUMIFS($L25:$AR25,$L$5:$AR$5,BA$5) -> 0 | ... BD25: =-SUMIFS($L25:$AR25,$L$5:$AR$5,BD$5) -> 0 | BF25: =SUM(AT25:BD25) -> -15000
A26: 1 | B26: Photography F&B | D26: Marketing | E26: Aniek | F26: 2000 | G26: =SUMIFS($L26:$AR26,$L$7:$AR$7,"<="&$J$4) -> 0 | H26: =J26-G26 -> 2000 | J26: =SUM(L26:AR26) -> 2000 | L26: =SUMIFS('Invoices - Preopening'!$I$20:$I$299,'Invoices - Preopening'!$H$20:$H$299,">="&L$6,'Invoices - Preopening'!$H$20:$H$299,"<="&L$7,'Invoices - Preopening'!$C$20:$C$299,'Model - Preopening & Fees'!$B26) -> 0 | M26: =SUMIFS('Invoices - Preopening'!$I$20:$I$299,'Invoices - Preopening'!$H$20:$H$299,">="&M$6,'Invoices - Preopening'!$H$20:$H$299,"<="&M$7,'Invoices - Preopening'!$C$20:$C$299,'Model - Preopening & Fees'!$B26) -> 0 | N26: =SUMIFS('Invoices - Preopening'!$I$20:$I$299,'Invoices - Preopening'!$H$20:$H$299,">="&N$6,'Invoices - Preopening'!$H$20:$H$299,"<="&N$7,'Invoices - Preopening'!$C$20:$C$299,'Model - Preopening & Fees'!$B26) -> 0 | O26: =SUMIFS('Invoices - Preopening'!$I$20:$I$299,'Invoices - Preopening'!$H$20:$H$299,">="&O$6,'Invoices - Preopening'!$H$20:$H$299,"<="&O$7,'Invoices - Preopening'!$C$20:$C$299,'Model - Preopening & Fees'!$B26) -> 0 | P26: =SUMIFS('Invoices - Preopening'!$I$20:$I$299,'Invoices - Preopening'!$H$20:$H$299,">="&P$6,'Invoices - Preopening'!$H$20:$H$299,"<="&P$7,'Invoices - Preopening'!$C$20:$C$299,'Model - Preopening & Fees'!$B26) -> 0 | Q26: =SUMIFS('Invoices - Preopening'!$I$20:$I$299,'Invoices - Preopening'!$H$20:$H$299,">="&Q$6,'Invoices - Preopening'!$H$20:$H$299,"<="&Q$7,'Invoices - Preopening'!$C$20:$C$299,'Model - Preopening & Fees'!$B26) -> 0 | R26: =SUMIFS('Invoices - Preopening'!$I$20:$I$299,'Invoices - Preopening'!$H$20:$H$299,">="&R$6,'Invoices - Preopening'!$H$20:$H$299,"<="&R$7,'Invoices - Preopening'!$C$20:$C$299,'Model - Preopening & Fees'!$B26) -> 0 | S26: =SUMIFS('Invoices - Preopening'!$I$20:$I$299,'Invoices - Preopening'!$H$20:$H$299,">="&S$6,'Invoices - Preopening'!$H$20:$H$299,"<="&S$7,'Invoices - Preopening'!$C$20:$C$299,'Model - Preopening & Fees'!$B26) -> 0 | ... AC26: =SUMIFS('Invoices - Preopening'!$I$20:$I$299,'Invoices - Preopening'!$H$20:$H$299,">="&AC$6,'Invoices - Preopening'!$H$20:$H$299,"<="&AC$7,'Invoices - Preopening'!$C$20:$C$299,'Model - Preopening & Fees'!$B26) -> 0 | AD26: 0 | AE26: 0 | AF26: 0 | AG26: 0 | AH26: 0 | AI26: 0 | AJ26: 0 | AK26: 2000 | AL26: 0 | AM26: 0 | AN26: 0 | AO26: 0 | AP26: 0 | AQ26: 0 | AR26: 0 | AT26: =-SUMIFS($L26:$AR26,$L$5:$AR$5,AT$5) -> 0 | AU26: =-SUMIFS($L26:$AR26,$L$5:$AR$5,AU$5) -> 0 | AV26: =-SUMIFS($L26:$AR26,$L$5:$AR$5,AV$5) -> 0 | AW26: =-SUMIFS($L26:$AR26,$L$5:$AR$5,AW$5) -> 0 | AX26: =-SUMIFS($L26:$AR26,$L$5:$AR$5,AX$5) -> 0 | AY26: =-SUMIFS($L26:$AR26,$L$5:$AR$5,AY$5) -> 0 | AZ26: =-SUMIFS($L26:$AR26,$L$5:$AR$5,AZ$5) -> 0 | BA26: =-SUMIFS($L26:$AR26,$L$5:$AR$5,BA$5) -> 0 | ... BD26: =-SUMIFS($L26:$AR26,$L$5:$AR$5,BD$5) -> 0 | BF26: =SUM(AT26:BD26) -> -2000
B28: Social Media
A29: 1 | B29: Influencer Fees | D29: Marketing | E29: Aniek | F29: 13200 | G29: =SUMIFS($L29:$AR29,$L$7:$AR$7,"<="&$J$4) -> 0 | H29: =J29-G29 -> 11200 | J29: =SUM(L29:AR29) -> 11200 | L29: =SUMIFS('Invoices - Preopening'!$I$20:$I$299,'Invoices - Preopening'!$H$20:$H$299,">="&L$6,'Invoices - Preopening'!$H$20:$H$299,"<="&L$7,'Invoices - Preopening'!$C$20:$C$299,'Model - Preopening & Fees'!$B29) -> 0 | M29: =SUMIFS('Invoices - Preopening'!$I$20:$I$299,'Invoices - Preopening'!$H$20:$H$299,">="&M$6,'Invoices - Preopening'!$H$20:$H$299,"<="&M$7,'Invoices - Preopening'!$C$20:$C$299,'Model - Preopening & Fees'!$B29) -> 0 | N29: =SUMIFS('Invoices - Preopening'!$I$20:$I$299,'Invoices - Preopening'!$H$20:$H$299,">="&N$6,'Invoices - Preopening'!$H$20:$H$299,"<="&N$7,'Invoices - Preopening'!$C$20:$C$299,'Model - Preopening & Fees'!$B29) -> 0 | O29: =SUMIFS('Invoices - Preopening'!$I$20:$I$299,'Invoices - Preopening'!$H$20:$H$299,">="&O$6,'Invoices - Preopening'!$H$20:$H$299,"<="&O$7,'Invoices - Preopening'!$C$20:$C$299,'Model - Preopening & Fees'!$B29) -> 0 | P29: =SUMIFS('Invoices - Preopening'!$I$20:$I$299,'Invoices - Preopening'!$H$20:$H$299,">="&P$6,'Invoices - Preopening'!$H$20:$H$299,"<="&P$7,'Invoices - Preopening'!$C$20:$C$299,'Model - Preopening & Fees'!$B29) -> 0 | Q29: =SUMIFS('Invoices - Preopening'!$I$20:$I$299,'Invoices - Preopening'!$H$20:$H$299,">="&Q$6,'Invoices - Preopening'!$H$20:$H$299,"<="&Q$7,'Invoices - Preopening'!$C$20:$C$299,'Model - Preopening & Fees'!$B29) -> 0 | R29: =SUMIFS('Invoices - Preopening'!$I$20:$I$299,'Invoices - Preopening'!$H$20:$H$299,">="&R$6,'Invoices - Preopening'!$H$20:$H$299,"<="&R$7,'Invoices - Preopening'!$C$20:$C$299,'Model - Preopening & Fees'!$B29) -> 0 | S29: =SUMIFS('Invoices - Preopening'!$I$20:$I$299,'Invoices - Preopening'!$H$20:$H$299,">="&S$6,'Invoices - Preopening'!$H$20:$H$299,"<="&S$7,'Invoices - Preopening'!$C$20:$C$299,'Model - Preopening & Fees'!$B29) -> 0 | ... AC29: =SUMIFS('Invoices - Preopening'!$I$20:$I$299,'Invoices - Preopening'!$H$20:$H$299,">="&AC$6,'Invoices - Preopening'!$H$20:$H$299,"<="&AC$7,'Invoices - Preopening'!$C$20:$C$299,'Model - Preopening & Fees'!$B29) -> 0 | AD29: 0 | AE29: 0 | AF29: 0 | AG29: 0 | AH29: 0 | AI29: 0 | AJ29: 0 | AK29: 2300 | AL29: 4400 | AM29: 4500 | AN29: 0 | AO29: 0 | AP29: 0 | AQ29: 0 | AR29: 0 | AT29: =-SUMIFS($L29:$AR29,$L$5:$AR$5,AT$5) -> 0 | AU29: =-SUMIFS($L29:$AR29,$L$5:$AR$5,AU$5) -> 0 | AV29: =-SUMIFS($L29:$AR29,$L$5:$AR$5,AV$5) -> 0 | AW29: =-SUMIFS($L29:$AR29,$L$5:$AR$5,AW$5) -> 0 | AX29: =-SUMIFS($L29:$AR29,$L$5:$AR$5,AX$5) -> 0 | AY29: =-SUMIFS($L29:$AR29,$L$5:$AR$5,AY$5) -> 0 | AZ29: =-SUMIFS($L29:$AR29,$L$5:$AR$5,AZ$5) -> 0 | BA29: =-SUMIFS($L29:$AR29,$L$5:$AR$5,BA$5) -> 0 | ... BD29: =-SUMIFS($L29:$AR29,$L$5:$AR$5,BD$5) -> 0 | BF29: =SUM(AT29:BD29) -> -11200
A30: 1 | B30: Boosting Organic Content | D30: Marketing | E30: Aniek | F30: 1600 | G30: =SUMIFS($L30:$AR30,$L$7:$AR$7,"<="&$J$4) -> 0 | H30: =J30-G30 -> 800 | J30: =SUM(L30:AR30) -> 800 | L30: =SUMIFS('Invoices - Preopening'!$I$20:$I$299,'Invoices - Preopening'!$H$20:$H$299,">="&L$6,'Invoices - Preopening'!$H$20:$H$299,"<="&L$7,'Invoices - Preopening'!$C$20:$C$299,'Model - Preopening & Fees'!$B30) -> 0 | M30: =SUMIFS('Invoices - Preopening'!$I$20:$I$299,'Invoices - Preopening'!$H$20:$H$299,">="&M$6,'Invoices - Preopening'!$H$20:$H$299,"<="&M$7,'Invoices - Preopening'!$C$20:$C$299,'Model - Preopening & Fees'!$B30) -> 0 | N30: =SUMIFS('Invoices - Preopening'!$I$20:$I$299,'Invoices - Preopening'!$H$20:$H$299,">="&N$6,'Invoices - Preopening'!$H$20:$H$299,"<="&N$7,'Invoices - Preopening'!$C$20:$C$299,'Model - Preopening & Fees'!$B30) -> 0 | O30: =SUMIFS('Invoices - Preopening'!$I$20:$I$299,'Invoices - Preopening'!$H$20:$H$299,">="&O$6,'Invoices - Preopening'!$H$20:$H$299,"<="&O$7,'Invoices - Preopening'!$C$20:$C$299,'Model - Preopening & Fees'!$B30) -> 0 | P30: =SUMIFS('Invoices - Preopening'!$I$20:$I$299,'Invoices - Preopening'!$H$20:$H$299,">="&P$6,'Invoices - Preopening'!$H$20:$H$299,"<="&P$7,'Invoices - Preopening'!$C$20:$C$299,'Model - Preopening & Fees'!$B30) -> 0 | Q30: =SUMIFS('Invoices - Preopening'!$I$20:$I$299,'Invoices - Preopening'!$H$20:$H$299,">="&Q$6,'Invoices - Preopening'!$H$20:$H$299,"<="&Q$7,'Invoices - Preopening'!$C$20:$C$299,'Model - Preopening & Fees'!$B30) -> 0 | R30: =SUMIFS('Invoices - Preopening'!$I$20:$I$299,'Invoices - Preopening'!$H$20:$H$299,">="&R$6,'Invoices - Preopening'!$H$20:$H$299,"<="&R$7,'Invoices - Preopening'!$C$20:$C$299,'Model - Preopening & Fees'!$B30) -> 0 | S30: =SUMIFS('Invoices - Preopening'!$I$20:$I$299,'Invoices - Preopening'!$H$20:$H$299,">="&S$6,'Invoices - Preopening'!$H$20:$H$299,"<="&S$7,'Invoices - Preopening'!$C$20:$C$299,'Model - Preopening & Fees'!$B30) -> 0 | ... AC30: =SUMIFS('Invoices - Preopening'!$I$20:$I$299,'Invoices - Preopening'!$H$20:$H$299,">="&AC$6,'Invoices - Preopening'!$H$20:$H$299,"<="&AC$7,'Invoices - Preopening'!$C$20:$C$299,'Model - Preopening & Fees'!$B30) -> 0 | AD30: 0 | AE30: 0 | AF30: 0 | AG30: 200 | AH30: 200 | AI30: 200 | AJ30: 200 | AK30: 0 | AL30: 0 | AM30: 0 | AN30: 0 | AO30: 0 | AP30: 0 | AQ30: 0 | AR30: 0 | AT30: =-SUMIFS($L30:$AR30,$L$5:$AR$5,AT$5) -> 0 | AU30: =-SUMIFS($L30:$AR30,$L$5:$AR$5,AU$5) -> 0 | AV30: =-SUMIFS($L30:$AR30,$L$5:$AR$5,AV$5) -> 0 | AW30: =-SUMIFS($L30:$AR30,$L$5:$AR$5,AW$5) -> 0 | AX30: =-SUMIFS($L30:$AR30,$L$5:$AR$5,AX$5) -> 0 | AY30: =-SUMIFS($L30:$AR30,$L$5:$AR$5,AY$5) -> 0 | AZ30: =-SUMIFS($L30:$AR30,$L$5:$AR$5,AZ$5) -> 0 | BA30: =-SUMIFS($L30:$AR30,$L$5:$AR$5,BA$5) -> -600 | ... BD30: =-SUMIFS($L30:$AR30,$L$5:$AR$5,BD$5) -> 0 | BF30: =SUM(AT30:BD30) -> -800
B32: Online Marketing / Paid Media
A33: 1 | B33: Diginauts Retainer (Sep 2026 till April 2027) | D33: Marketing | E33: Aniek | F33: 7832 | G33: =SUMIFS($L33:$AR33,$L$7:$AR$7,"<="&$J$4) -> 0 | H33: =J33-G33 -> 5548 | J33: =SUM(L33:AR33) -> 5548 | L33: =SUMIFS('Invoices - Preopening'!$I$20:$I$299,'Invoices - Preopening'!$H$20:$H$299,">="&L$6,'Invoices - Preopening'!$H$20:$H$299,"<="&L$7,'Invoices - Preopening'!$C$20:$C$299,'Model - Preopening & Fees'!$B33) -> 0 | M33: =SUMIFS('Invoices - Preopening'!$I$20:$I$299,'Invoices - Preopening'!$H$20:$H$299,">="&M$6,'Invoices - Preopening'!$H$20:$H$299,"<="&M$7,'Invoices - Preopening'!$C$20:$C$299,'Model - Preopening & Fees'!$B33) -> 0 | N33: =SUMIFS('Invoices - Preopening'!$I$20:$I$299,'Invoices - Preopening'!$H$20:$H$299,">="&N$6,'Invoices - Preopening'!$H$20:$H$299,"<="&N$7,'Invoices - Preopening'!$C$20:$C$299,'Model - Preopening & Fees'!$B33) -> 0 | O33: =SUMIFS('Invoices - Preopening'!$I$20:$I$299,'Invoices - Preopening'!$H$20:$H$299,">="&O$6,'Invoices - Preopening'!$H$20:$H$299,"<="&O$7,'Invoices - Preopening'!$C$20:$C$299,'Model - Preopening & Fees'!$B33) -> 0 | P33: =SUMIFS('Invoices - Preopening'!$I$20:$I$299,'Invoices - Preopening'!$H$20:$H$299,">="&P$6,'Invoices - Preopening'!$H$20:$H$299,"<="&P$7,'Invoices - Preopening'!$C$20:$C$299,'Model - Preopening & Fees'!$B33) -> 0 | Q33: =SUMIFS('Invoices - Preopening'!$I$20:$I$299,'Invoices - Preopening'!$H$20:$H$299,">="&Q$6,'Invoices - Preopening'!$H$20:$H$299,"<="&Q$7,'Invoices - Preopening'!$C$20:$C$299,'Model - Preopening & Fees'!$B33) -> 0 | R33: =SUMIFS('Invoices - Preopening'!$I$20:$I$299,'Invoices - Preopening'!$H$20:$H$299,">="&R$6,'Invoices - Preopening'!$H$20:$H$299,"<="&R$7,'Invoices - Preopening'!$C$20:$C$299,'Model - Preopening & Fees'!$B33) -> 0 | S33: =SUMIFS('Invoices - Preopening'!$I$20:$I$299,'Invoices - Preopening'!$H$20:$H$299,">="&S$6,'Invoices - Preopening'!$H$20:$H$299,"<="&S$7,'Invoices - Preopening'!$C$20:$C$299,'Model - Preopening & Fees'!$B33) -> 0 | ... AC33: =SUMIFS('Invoices - Preopening'!$I$20:$I$299,'Invoices - Preopening'!$H$20:$H$299,">="&AC$6,'Invoices - Preopening'!$H$20:$H$299,"<="&AC$7,'Invoices - Preopening'!$C$20:$C$299,'Model - Preopening & Fees'!$B33) -> 0 | AD33: 0 | AE33: 0 | AF33: 460 | AG33: 460 | AH33: 1157 | AI33: 1157 | AJ33: 1157 | AK33: 1157 | AL33: 0 | AM33: 0 | AN33: 0 | AO33: 0 | AP33: 0 | AQ33: 0 | AR33: 0 | AT33: =-SUMIFS($L33:$AR33,$L$5:$AR$5,AT$5) -> 0 | AU33: =-SUMIFS($L33:$AR33,$L$5:$AR$5,AU$5) -> 0 | AV33: =-SUMIFS($L33:$AR33,$L$5:$AR$5,AV$5) -> 0 | AW33: =-SUMIFS($L33:$AR33,$L$5:$AR$5,AW$5) -> 0 | AX33: =-SUMIFS($L33:$AR33,$L$5:$AR$5,AX$5) -> 0 | AY33: =-SUMIFS($L33:$AR33,$L$5:$AR$5,AY$5) -> 0 | AZ33: =-SUMIFS($L33:$AR33,$L$5:$AR$5,AZ$5) -> -460 | BA33: =-SUMIFS($L33:$AR33,$L$5:$AR$5,BA$5) -> -2774 | ... BD33: =-SUMIFS($L33:$AR33,$L$5:$AR$5,BD$5) -> 0 | BF33: =SUM(AT33:BD33) -> -5548
