Workbook

Sheet Overview
B1: OS&E_FF&E Overview
B3: Hotel | C3: The Usual Florence
B4: Brand | C4: The Usual
B5: Status
A7: Package | B7: OSE_FFE | C7: Loose OS&E/Daan/Usual | D7: Budget Artelia | E7: Comments | F7: ordered | G7: deadline | H7: In charge | I7: Information submitted to Daan
A8: P1.0 | B8: F&B: Fixed Kitchen & Bar Equipment | C8: =SUMIF('OS&E_FF&E'!$A:$A,Overview!$A8,'OS&E_FF&E'!$H:$H) -> 0 | H8: Michael
A9: P1.1 | B9: F&B: Coffee equipment | C9: =SUMIF('OS&E_FF&E'!$A:$A,Overview!$A9,'OS&E_FF&E'!$H:$H) -> 0 | H9: Michael
A10: P1.2 | B10: F&B: Operating Systems | C10: =SUMIF('OS&E_FF&E'!$A:$A,Overview!$A10,'OS&E_FF&E'!$H:$H) -> 0 | H10: Michael
A11: P1.3 | B11: F&B: Operating Equipment F&B | C11: 0 | H11: Michael | I11: P1.0 to P1.4: All part of capex 300K
A12: P2 | B12: Branded Stationary | C12: =SUMIF('OS&E_FF&E'!$A:$A,Overview!$A12,'OS&E_FF&E'!$H:$H) -> 25139.41 | H12: Marketing
A13: P3 | B13: Loose Furniture rooms | C13: =SUMIF('OS&E_FF&E'!$A:$A,Overview!$A13,'OS&E_FF&E'!$H:$H) -> 0 | H13: Gisela | I13: TPC
A14: P4 | B14: Linen | C14: =SUMIF('OS&E_FF&E'!$A:$A,Overview!$A14,'OS&E_FF&E'!$H:$H) -> 46800 | H14: Gisela
A15: P5 | B15: Transport & Installation | C15: =SUMIF('OS&E_FF&E'!$A:$A,Overview!$A15,'OS&E_FF&E'!$H:$H) -> 12400 | H15: Michiel | I15: Moving Company + assistance GC
A16: P6 | B16: Events equipment | C16: =SUMIF('OS&E_FF&E'!$A:$A,Overview!$A16,'OS&E_FF&E'!$H:$H) -> 0
A17: P7 | B17: Guestroom equipment and support | C17: =SUMIF('OS&E_FF&E'!$A:$A,Overview!$A17,'OS&E_FF&E'!$H:$H) -> 3787 | H17: Gisela | I17: toothbrush/paste/shavingkit etc.
A18: P8 | B18: Cleaning equipment and tools | C18: =SUMIF('OS&E_FF&E'!$A:$A,Overview!$A18,'OS&E_FF&E'!$H:$H) -> 5050 | H18: HM/Andi | I18: TD equipment
A19: P9 | B19: Wardrobe (uniforms) | C19: =SUMIF('OS&E_FF&E'!$A:$A,Overview!$A19,'OS&E_FF&E'!$H:$H) -> 5000 | H19: Marketing | I19: Uniforms Sweaters
A20: P10 | B20: Storeroom and pantry shelving | H20: HM/Andi | I20: In FF&E/OS&E groundfloor budget (total 51K)
A21: P11 | B21: FF&E PA | H21: Michiel | I21: Artelia capex FF&E groiundfloor
A22: P12 | B22: Wellness, fitness and recreational equipment | H22: Gisela | I22: 20K in budget Artelia
A23: P13 | B23: Baby items | C23: =SUMIF('OS&E_FF&E'!$A:$A,Overview!$A23,'OS&E_FF&E'!$H:$H) -> 713 | H23: HM/Andi
A24: P14 | B24: Office furniture & equipment | H24: HM/Andi | I24: In FF&E/OS&E groundfloor budget (total 51K)
A25: P15 | B25: Public areas accessories | C25: =SUMIF('OS&E_FF&E'!$A:$A,Overview!$A25,'OS&E_FF&E'!$H:$H) -> 6550 | H25: Gisela | I25: Bins public space
A26: P16 | B26: Art & accessories Rooms | H26: Gisela | I26: pictures rooms and statue:TPC and Art budget
A27: P17 | B27: IT | H27: Marc | I27: incl in capex
A28: P18 | B28: FF&E rooms | C28: =SUMIF('OS&E_FF&E'!$A:$A,Overview!$A28,'OS&E_FF&E'!$H:$H) -> 0 | H28: Michiel | I28: Incl in capex
A29: P19 | B29: internal signage | H29: Gisela | I29: Design Stylt 7.5K, rest in capex budget OS&e Groundfloor
A30: P20 | B30: OS&E Rooms | C30: =SUMIF('OS&E_FF&E'!$A:$A,Overview!$A30,'OS&E_FF&E'!$H:$H) -> 10645 | H30: Gisela | I30: Items excluded TPC contract
A31: P21 | B31: Plants | C31: =SUMIF('OS&E_FF&E'!$A:$A,Overview!$A31,'OS&E_FF&E'!$H:$H) -> 15000 | H31: HM/Andi | I31: not in Capex
A32: P22 | B32: Operational Equipment | C32: =SUMIF('OS&E_FF&E'!$A:$A,Overview!$A32,'OS&E_FF&E'!$H:$H) -> 16250.5 | H32: HM/Andi | I32: Marie Stella Maris + 7.5 K qwashmachine etc
A33: P23 | B33: Health & safety | C33: =SUMIF('OS&E_FF&E'!$A:$A,Overview!$A33,'OS&E_FF&E'!$H:$H) -> 2562 | H33: HM/Andi
B35: Total: | C35: =SUM(C8:C33) -> 149896.91 | D35: =SUM(D8:D33) -> 0
B37: total OS&E budget (file budget all dept 27 jan 2026) | C37: 165000
B38: total costs column C: purchase bij UHG | C38: =C35 -> 149896.91
B39: Contigency various items | C39: =-(C38-C37) -> 15103.09

Sheet OS&E_FF&E
A1: Package | C1: Items | D1: Item nr. | E1: Quantity | F1: Supplier | G1: Unit Price | H1: Total | I1: Picture/discription | J1: date of arrival | K1: order placed
A2: P1.0 | B2: =IF(INDEX(Overview!$C$8:$C$33,MATCH('OS&E_FF&E'!A2,Overview!$A$8:$A$33,0))=0,0,1) -> 0 | C2: Induction hot plate round (drop-in) | D2: F&B Wall / Grab & Go | E2: 0 | F2: Beuk - 63564 | G2: 2000 | H2: =E2*G2 -> 0 | L2: =INDEX(Overview!$B$8:$B$33,MATCH('OS&E_FF&E'!$A2,Overview!$A$8:$A$33,0)) -> F&B: Fixed Kitchen & Bar Equipment
A3: P1.0 | B3: =IF(INDEX(Overview!$C$8:$C$33,MATCH('OS&E_FF&E'!A3,Overview!$A$8:$A$33,0))=0,0,1) -> 0 | C3: Scholl Heat lamp | D3: F&B Wall / Grab & Go | E3: 0 | F3: Beuk - 63564 | G3: 350 | H3: =E3*G3 -> 0 | L3: =INDEX(Overview!$B$8:$B$33,MATCH('OS&E_FF&E'!$A3,Overview!$A$8:$A$33,0)) -> F&B: Fixed Kitchen & Bar Equipment
A4: P1.0 | B4: =IF(INDEX(Overview!$C$8:$C$33,MATCH('OS&E_FF&E'!A4,Overview!$A$8:$A$33,0))=0,0,1) -> 0 | C4: Double door refridgerator (black) | D4: F&B Wall / Grab & Go | E4: 0 | F4: Beuk - 63564 | G4: 3950 | H4: =E4*G4 -> 0 | L4: =INDEX(Overview!$B$8:$B$33,MATCH('OS&E_FF&E'!$A4,Overview!$A$8:$A$33,0)) -> F&B: Fixed Kitchen & Bar Equipment
A5: P1.0 | B5: =IF(INDEX(Overview!$C$8:$C$33,MATCH('OS&E_FF&E'!A5,Overview!$A$8:$A$33,0))=0,0,1) -> 0 | C5: Custom made stainless steel sink/work/dispensing furniture | D5: Kitchen equipment & appliances | E5: 0 | F5: Beuk - 63564 | G5: 9716 | H5: =E5*G5 -> 0 | L5: =INDEX(Overview!$B$8:$B$33,MATCH('OS&E_FF&E'!$A5,Overview!$A$8:$A$33,0)) -> F&B: Fixed Kitchen & Bar Equipment
A6: P1.0 | B6: =IF(INDEX(Overview!$C$8:$C$33,MATCH('OS&E_FF&E'!A6,Overview!$A$8:$A$33,0))=0,0,1) -> 0 | C6: Solid water tap with 1-lever / elbow control | D6: Kitchen equipment & appliances | E6: 0 | F6: Beuk - 63564 | G6: 175 | H6: =E6*G6 -> 0 | L6: =INDEX(Overview!$B$8:$B$33,MATCH('OS&E_FF&E'!$A6,Overview!$A$8:$A$33,0)) -> F&B: Fixed Kitchen & Bar Equipment
A7: P1.0 | B7: =IF(INDEX(Overview!$C$8:$C$33,MATCH('OS&E_FF&E'!A7,Overview!$A$8:$A$33,0))=0,0,1) -> 0 | C7: Rubbermaid waste container (with dolly) | D7: Kitchen equipment & appliances | E7: 0 | F7: Beuk - 63564 | G7: 130 | H7: =E7*G7 -> 0 | L7: =INDEX(Overview!$B$8:$B$33,MATCH('OS&E_FF&E'!$A7,Overview!$A$8:$A$33,0)) -> F&B: Fixed Kitchen & Bar Equipment
A8: P1.0 | B8: =IF(INDEX(Overview!$C$8:$C$33,MATCH('OS&E_FF&E'!A8,Overview!$A$8:$A$33,0))=0,0,1) -> 0 | C8: Roeder refrigerated workbench | D8: Kitchen equipment & appliances | E8: 0 | F8: Beuk - 63564 | G8: 3360 | H8: =E8*G8 -> 0 | L8: =INDEX(Overview!$B$8:$B$33,MATCH('OS&E_FF&E'!$A8,Overview!$A$8:$A$33,0)) -> F&B: Fixed Kitchen & Bar Equipment
A9: P1.0 | B9: =IF(INDEX(Overview!$C$8:$C$33,MATCH('OS&E_FF&E'!A9,Overview!$A$8:$A$33,0))=0,0,1) -> 0 | C9: Alto-Shaam warming cabinet | D9: Kitchen equipment & appliances | E9: 0 | F9: Beuk - 63564 | G9: 5695 | H9: =E9*G9 -> 0 | L9: =INDEX(Overview!$B$8:$B$33,MATCH('OS&E_FF&E'!$A9,Overview!$A$8:$A$33,0)) -> F&B: Fixed Kitchen & Bar Equipment
A10: P1.0 | B10: =IF(INDEX(Overview!$C$8:$C$33,MATCH('OS&E_FF&E'!A10,Overview!$A$8:$A$33,0))=0,0,1) -> 0 | C10: Vector Multi Cook Oven | D10: Kitchen equipment & appliances | E10: 0 | F10: Beuk - 63564 | G10: 28500 | H10: =E10*G10 -> 0 | L10: =INDEX(Overview!$B$8:$B$33,MATCH('OS&E_FF&E'!$A10,Overview!$A$8:$A$33,0)) -> F&B: Fixed Kitchen & Bar Equipment
A11: P1.0 | B11: =IF(INDEX(Overview!$C$8:$C$33,MATCH('OS&E_FF&E'!A11,Overview!$A$8:$A$33,0))=0,0,1) -> 0 | C11: Rational iCombi Pro Combisteamer | D11: Kitchen equipment & appliances | E11: 0 | F11: Beuk - 63564 | G11: 10570 | H11: =E11*G11 -> 0 | L11: =INDEX(Overview!$B$8:$B$33,MATCH('OS&E_FF&E'!$A11,Overview!$A$8:$A$33,0)) -> F&B: Fixed Kitchen & Bar Equipment
A12: P1.0 | B12: =IF(INDEX(Overview!$C$8:$C$33,MATCH('OS&E_FF&E'!A12,Overview!$A$8:$A$33,0))=0,0,1) -> 0 | C12: UltraVent Condensation Hood | D12: Kitchen equipment & appliances | E12: 0 | F12: Qualitytec Quote via Artelia, partly instalation budget tbd.. | G12: 33766 | H12: =E12*G12 -> 0 | L12: =INDEX(Overview!$B$8:$B$33,MATCH('OS&E_FF&E'!$A12,Overview!$A$8:$A$33,0)) -> F&B: Fixed Kitchen & Bar Equipment
A13: P1.0 | B13: =IF(INDEX(Overview!$C$8:$C$33,MATCH('OS&E_FF&E'!A13,Overview!$A$8:$A$33,0))=0,0,1) -> 0 | C13: Custom made stainless steel double wall shelf | D13: Kitchen equipment & appliances | E13: 0 | F13: Beuk - 63564 | G13: 1106 | H13: =E13*G13 -> 0 | L13: =INDEX(Overview!$B$8:$B$33,MATCH('OS&E_FF&E'!$A13,Overview!$A$8:$A$33,0)) -> F&B: Fixed Kitchen & Bar Equipment
... A27: P1.0 | B27: =IF(INDEX(Overview!$C$8:$C$33,MATCH('OS&E_FF&E'!A27,Overview!$A$8:$A$33,0))=0,0,1) -> 0 | C27: Cocktail bar | D27: Bar equipment & appliances | E27: 0 | F27: Beuk - 63564 | G27: 4650 | H27: =E27*G27 -> 0 | L27: =INDEX(Overview!$B$8:$B$33,MATCH('OS&E_FF&E'!$A27,Overview!$A$8:$A$33,0)) -> F&B: Fixed Kitchen & Bar Equipment
A28: P1.0 | B28: =IF(INDEX(Overview!$C$8:$C$33,MATCH('OS&E_FF&E'!A28,Overview!$A$8:$A$33,0))=0,0,1) -> 0 | C28: Gamko bar cooling (for milk) | D28: Bar equipment & appliances | E28: 0 | G28: 1470 | H28: =E28*G28 -> 0 | L28: =INDEX(Overview!$B$8:$B$33,MATCH('OS&E_FF&E'!$A28,Overview!$A$8:$A$33,0)) -> F&B: Fixed Kitchen & Bar Equipment
A29: P1.0 | B29: =IF(INDEX(Overview!$C$8:$C$33,MATCH('OS&E_FF&E'!A29,Overview!$A$8:$A$33,0))=0,0,1) -> 0 | C29: Pastry display (build-in) | D29: Bar equipment & appliances | E29: 0 | G29: 0 | H29: =E29*G29 -> 0 | L29: =INDEX(Overview!$B$8:$B$33,MATCH('OS&E_FF&E'!$A29,Overview!$A$8:$A$33,0)) -> F&B: Fixed Kitchen & Bar Equipment
A30: P1.0 | B30: =IF(INDEX(Overview!$C$8:$C$33,MATCH('OS&E_FF&E'!A30,Overview!$A$8:$A$33,0))=0,0,1) -> 0 | C30: Custom made stainless steel debrasing/feeding table with basket guideer racks | D30: Stewarding equipment & appliances | E30: 0 | F30: Beuk - 63564 | G30: 2972 | H30: =E30*G30 -> 0 | L30: =INDEX(Overview!$B$8:$B$33,MATCH('OS&E_FF&E'!$A30,Overview!$A$8:$A$33,0)) -> F&B: Fixed Kitchen & Bar Equipment
A31: P1.0 | B31: =IF(INDEX(Overview!$C$8:$C$33,MATCH('OS&E_FF&E'!A31,Overview!$A$8:$A$33,0))=0,0,1) -> 0 | C31: Pre-rinse shower (with tap) | D31: Stewarding equipment & appliances | E31: 0 | F31: Beuk - 63564 | G31: 315 | H31: =E31*G31 -> 0 | L31: =INDEX(Overview!$B$8:$B$33,MATCH('OS&E_FF&E'!$A31,Overview!$A$8:$A$33,0)) -> F&B: Fixed Kitchen & Bar Equipment
A32: P1.0 | B32: =IF(INDEX(Overview!$C$8:$C$33,MATCH('OS&E_FF&E'!A32,Overview!$A$8:$A$33,0))=0,0,1) -> 0 | C32: Rubbermaid waste container (with dolly) | D32: Stewarding equipment & appliances | E32: 0 | F32: Beuk - 63564 | G32: 130 | H32: =E32*G32 -> 0 | L32: =INDEX(Overview!$B$8:$B$33,MATCH('OS&E_FF&E'!$A32,Overview!$A$8:$A$33,0)) -> F&B: Fixed Kitchen & Bar Equipment
A33: P1.0 | B33: =IF(INDEX(Overview!$C$8:$C$33,MATCH('OS&E_FF&E'!A33,Overview!$A$8:$A$33,0))=0,0,1) -> 0 | C33: Custom made stainless steel debrasingshelf | D33: Stewarding equipment & appliances | E33: 0 | F33: Beuk - 63564 | G33: 996 | H33: =E33*G33 -> 0 | L33: =INDEX(Overview!$B$8:$B$33,MATCH('OS&E_FF&E'!$A33,Overview!$A$8:$A$33,0)) -> F&B: Fixed Kitchen & Bar Equipment
A34: P1.0 | B34: =IF(INDEX(Overview!$C$8:$C$33,MATCH('OS&E_FF&E'!A34,Overview!$A$8:$A$33,0))=0,0,1) -> 0 | C34: Rhima prewashing machine | D34: Stewarding equipment & appliances | E34: 0 | F34: Beuk - 63564 | G34: 5455 | H34: =E34*G34 -> 0 | L34: =INDEX(Overview!$B$8:$B$33,MATCH('OS&E_FF&E'!$A34,Overview!$A$8:$A$33,0)) -> F&B: Fixed Kitchen & Bar Equipment
A35: P1.0 | B35: =IF(INDEX(Overview!$C$8:$C$33,MATCH('OS&E_FF&E'!A35,Overview!$A$8:$A$33,0))=0,0,1) -> 0 | C35: Custom made stainless steel connector | D35: Stewarding equipment & appliances | E35: 0 | F35: Beuk - 63564 | G35: 395 | H35: =E35*G35 -> 0 | L35: =INDEX(Overview!$B$8:$B$33,MATCH('OS&E_FF&E'!$A35,Overview!$A$8:$A$33,0)) -> F&B: Fixed Kitchen & Bar Equipment
A36: P1.0 | B36: =IF(INDEX(Overview!$C$8:$C$33,MATCH('OS&E_FF&E'!A36,Overview!$A$8:$A$33,0))=0,0,1) -> 0 | C36: Rhima pass-through dishwasher with energy-saving steam condensing unit | D36: Stewarding equipment & appliances | E36: 0 | F36: Beuk - 63564 | G36: 13300 | H36: =E36*G36 -> 0 | L36: =INDEX(Overview!$B$8:$B$33,MATCH('OS&E_FF&E'!$A36,Overview!$A$8:$A$33,0)) -> F&B: Fixed Kitchen & Bar Equipment
A37: P1.0 | B37: =IF(INDEX(Overview!$C$8:$C$33,MATCH('OS&E_FF&E'!A37,Overview!$A$8:$A$33,0))=0,0,1) -> 0 | C37: Weighted boiler element | D37: Stewarding equipment & appliances | E37: 0 | F37: Beuk - 63564 | G37: 605 | H37: =E37*G37 -> 0 | L37: =INDEX(Overview!$B$8:$B$33,MATCH('OS&E_FF&E'!$A37,Overview!$A$8:$A$33,0)) -> F&B: Fixed Kitchen & Bar Equipment
A38: P1.0 | B38: =IF(INDEX(Overview!$C$8:$C$33,MATCH('OS&E_FF&E'!A38,Overview!$A$8:$A$33,0))=0,0,1) -> 0 | C38: Custom made stainless steel drain-/roller table | D38: Stewarding equipment & appliances | E38: 0 | F38: Beuk - 63564 | G38: 1786 | H38: =E38*G38 -> 0 | L38: =INDEX(Overview!$B$8:$B$33,MATCH('OS&E_FF&E'!$A38,Overview!$A$8:$A$33,0)) -> F&B: Fixed Kitchen & Bar Equipment
A39: P1.0 | B39: =IF(INDEX(Overview!$C$8:$C$33,MATCH('OS&E_FF&E'!A39,Overview!$A$8:$A$33,0))=0,0,1) -> 0 | C39: Rhima full-automatic volume-operated water descaler | D39: Stewarding equipment & appliances | E39: 0 | F39: Beuk - 63564 | G39: 1395 | H39: =E39*G39 -> 0 | L39: =INDEX(Overview!$B$8:$B$33,MATCH('OS&E_FF&E'!$A39,Overview!$A$8:$A$33,0)) -> F&B: Fixed Kitchen & Bar Equipment
A40: P1.0 | B40: =IF(INDEX(Overview!$C$8:$C$33,MATCH('OS&E_FF&E'!A40,Overview!$A$8:$A$33,0))=0,0,1) -> 0 | C40: Rhima Pro Wash Water softening salt | D40: Stewarding equipment & appliances | E40: 0 | F40: Beuk - 63564 | G40: 29 | H40: =E40*G40 -> 0 | L40: =INDEX(Overview!$B$8:$B$33,MATCH('OS&E_FF&E'!$A40,Overview!$A$8:$A$33,0)) -> F&B: Fixed Kitchen & Bar Equipment
A41: P1.0 | B41: =IF(INDEX(Overview!$C$8:$C$33,MATCH('OS&E_FF&E'!A41,Overview!$A$8:$A$33,0))=0,0,1) -> 0 | C41: Custom mode stainless steel cutlery sorting station | D41: Stewarding equipment & appliances | E41: 0 | F41: Beuk - 63564 | G41: 165 | H41: =E41*G41 -> 0 | L41: =INDEX(Overview!$B$8:$B$33,MATCH('OS&E_FF&E'!$A41,Overview!$A$8:$A$33,0)) -> F&B: Fixed Kitchen & Bar Equipment
... A45: P1.0 | B45: =IF(INDEX(Overview!$C$8:$C$33,MATCH('OS&E_FF&E'!A45,Overview!$A$8:$A$33,0))=0,0,1) -> 0 | C45: Custom cold storage/freezer room | D45: Storage (fridge, freezer & dry) | E45: 0 | F45: Querci Quote via Artelia | G45: 17560 | H45: =E45*G45 -> 0 | L45: =INDEX(Overview!$B$8:$B$33,MATCH('OS&E_FF&E'!$A45,Overview!$A$8:$A$33,0)) -> F&B: Fixed Kitchen & Bar Equipment
A46: P1.0 | B46: =IF(INDEX(Overview!$C$8:$C$33,MATCH('OS&E_FF&E'!A46,Overview!$A$8:$A$33,0))=0,0,1) -> 0 | C46: Fermostock HACCP 4 level shelf in U-shape | D46: Storage (fridge, freezer & dry) | E46: 0 | G46: 1850 | H46: =E46*G46 -> 0 | L46: =INDEX(Overview!$B$8:$B$33,MATCH('OS&E_FF&E'!$A46,Overview!$A$8:$A$33,0)) -> F&B: Fixed Kitchen & Bar Equipment
A47: P1.0 | B47: =IF(INDEX(Overview!$C$8:$C$33,MATCH('OS&E_FF&E'!A47,Overview!$A$8:$A$33,0))=0,0,1) -> 0 | C47: Fermostock HACCP 4 level shelf in U-shape | D47: Storage (fridge, freezer & dry) | E47: 0 | F47: Beuk - 63564 | G47: 1850 | H47: =E47*G47 -> 0 | L47: =INDEX(Overview!$B$8:$B$33,MATCH('OS&E_FF&E'!$A47,Overview!$A$8:$A$33,0)) -> F&B: Fixed Kitchen & Bar Equipment
A48: P1.0 | B48: =IF(INDEX(Overview!$C$8:$C$33,MATCH('OS&E_FF&E'!A48,Overview!$A$8:$A$33,0))=0,0,1) -> 0 | C48: Fermostock HACCP 5 level shelf in U-shape | D48: Storage (fridge, freezer & dry) | E48: 0 | F48: Beuk - 63564 | G48: 2250 | H48: =E48*G48 -> 0 | L48: =INDEX(Overview!$B$8:$B$33,MATCH('OS&E_FF&E'!$A48,Overview!$A$8:$A$33,0)) -> F&B: Fixed Kitchen & Bar Equipment
A49: P1.0 | B49: =IF(INDEX(Overview!$C$8:$C$33,MATCH('OS&E_FF&E'!A49,Overview!$A$8:$A$33,0))=0,0,1) -> 0 | C49: Projected installation costs | D49: Connection & placement fees | E49: 0 | F49: Beuk - 63564 | G49: 3500 | H49: =E49*G49 -> 0 | L49: =INDEX(Overview!$B$8:$B$33,MATCH('OS&E_FF&E'!$A49,Overview!$A$8:$A$33,0)) -> F&B: Fixed Kitchen & Bar Equipment
A50: P1.0 | B50: =IF(INDEX(Overview!$C$8:$C$33,MATCH('OS&E_FF&E'!A50,Overview!$A$8:$A$33,0))=0,0,1) -> 0 | C50: Projected transportation costs | D50: Transportation costs | E50: 0 | F50: Beuk - 63564 | G50: 6450 | H50: =E50*G50 -> 0 | L50: =INDEX(Overview!$B$8:$B$33,MATCH('OS&E_FF&E'!$A50,Overview!$A$8:$A$33,0)) -> F&B: Fixed Kitchen & Bar Equipment
A51: P1.0 | B51: =IF(INDEX(Overview!$C$8:$C$33,MATCH('OS&E_FF&E'!A51,Overview!$A$8:$A$33,0))=0,0,1) -> 0 | C51: Special EXTRA rounding and project discount on NETTO quote (on undivided order) | D51: Discount | E51: 0 | F51: Beuk - 63564 | G51: =-3542+50 -> -3492 | H51: =E51*G51 -> 0 | L51: =INDEX(Overview!$B$8:$B$33,MATCH('OS&E_FF&E'!$A51,Overview!$A$8:$A$33,0)) -> F&B: Fixed Kitchen & Bar Equipment
A52: P1.1 | B52: =IF(INDEX(Overview!$C$8:$C$33,MATCH('OS&E_FF&E'!A52,Overview!$A$8:$A$33,0))=0,0,1) -> 0 | C52: Single Jet 6 5.6 Kw | D52: Back of House | E52: 0 | G52: 2784.64 | H52: =E52*G52 -> 0 | L52: =INDEX(Overview!$B$8:$B$33,MATCH('OS&E_FF&E'!$A52,Overview!$A$8:$A$33,0)) -> F&B: Coffee equipment
A53: P1.1 | B53: =IF(INDEX(Overview!$C$8:$C$33,MATCH('OS&E_FF&E'!A53,Overview!$A$8:$A$33,0))=0,0,1) -> 0 | C53: URN | D53: Back of House | E53: 0 | G53: 591.64 | H53: =E53*G53 -> 0 | L53: =INDEX(Overview!$B$8:$B$33,MATCH('OS&E_FF&E'!$A53,Overview!$A$8:$A$33,0)) -> F&B: Coffee equipment
A54: P1.1 | B54: =IF(INDEX(Overview!$C$8:$C$33,MATCH('OS&E_FF&E'!A54,Overview!$A$8:$A$33,0))=0,0,1) -> 0 | C54: Jet grinder | D54: Back of House | E54: 0 | G54: 2141.79 | H54: =E54*G54 -> 0 | L54: =INDEX(Overview!$B$8:$B$33,MATCH('OS&E_FF&E'!$A54,Overview!$A$8:$A$33,0)) -> F&B: Coffee equipment
A55: P1.1 | B55: =IF(INDEX(Overview!$C$8:$C$33,MATCH('OS&E_FF&E'!A55,Overview!$A$8:$A$33,0))=0,0,1) -> 0 | C55: Transport | D55: Back of House | E55: 0 | G55: 350 | H55: =E55*G55 -> 0 | L55: =INDEX(Overview!$B$8:$B$33,MATCH('OS&E_FF&E'!$A55,Overview!$A$8:$A$33,0)) -> F&B: Coffee equipment
A56: P1.1 | B56: =IF(INDEX(Overview!$C$8:$C$33,MATCH('OS&E_FF&E'!A56,Overview!$A$8:$A$33,0))=0,0,1) -> 0 | C56: Full Automatic Spritz Bar tbd | D56: Back of House | E56: 0 | G56: 2000 | H56: =E56*G56 -> 0 | L56: =INDEX(Overview!$B$8:$B$33,MATCH('OS&E_FF&E'!$A56,Overview!$A$8:$A$33,0)) -> F&B: Coffee equipment
...

Sheet Blad1
A1: Item nr.
A2: F&B Wall / Grab & Go
A3: Kitchen equipment & appliances
A4: Bar equipment & appliances
A5: Stewarding equipment & appliances
A6: Storage (fridge, freezer & dry)
A7: Connection & placement fees
A8: Transportation costs
A9: Discount
A10: Back of House
A11: POS System
A12: Chinaware
... A46: Decoration

Sheet comments

Sheet Payment schedule
A1: Supplier | B1: Total | C1: payment terms | D1: Jan | E1: Feb | F1: Mrt | G1: Apr | H1: Mei | I1: Jun | J1: Jul | K1: Aug | L1: Sep | M1: Okt | N1: Nov | O1: Dec | P1: Comments:
A2: Crown International | B2: =SUMIF('OS&E_FF&E'!F:F,'Payment schedule'!A2,'OS&E_FF&E'!H:H) -> 0 | C2: 30% up front, 70% after delivery | H2: 8183.85 | M2: 19095.65
A3: Hilding Anders | B3: =SUMIF('OS&E_FF&E'!F:F,'Payment schedule'!A3,'OS&E_FF&E'!H:H) -> 0 | C3: 50% after order placement, 50% before delivery. | J3: 35636.73 | K3: 35636.72
A4: Essem Design | B4: =SUMIF('OS&E_FF&E'!F:F,'Payment schedule'!A4,'OS&E_FF&E'!H:H) -> 0
A5: Star Linen | B5: =SUMIF('OS&E_FF&E'!F:F,'Payment schedule'!A5,'OS&E_FF&E'!H:H) -> 0 | J5: 11033.38 | M5: 11033.38
A6: kingdom hotel supplies | B6: =SUMIF('OS&E_FF&E'!F:F,'Payment schedule'!A6,'OS&E_FF&E'!H:H) -> 653 | L6: 2357.5
A7: Stokke | B7: =SUMIF('OS&E_FF&E'!F:F,'Payment schedule'!A7,'OS&E_FF&E'!H:H) -> 320 | L7: 1074
A8: bol.com | B8: =SUMIF('OS&E_FF&E'!F:F,'Payment schedule'!A8,'OS&E_FF&E'!H:H) -> 0 | C8: 100% up front | K8: 951
A9: IME | B9: =SUMIF('OS&E_FF&E'!F:F,'Payment schedule'!A9,'OS&E_FF&E'!H:H) -> 9380 | C9: 50% after order placement, 30% before delivery, 20% 30 days after | J9: 9991.37 | L9: 5994.83 | M9: 3996.55
A10: Hobeka | B10: =SUMIF('OS&E_FF&E'!F:F,'Payment schedule'!A10,'OS&E_FF&E'!H:H) -> 0 | C10: 50% after order placement, 45% before delivery, 5% 30 days after. | J10: 5321.5 | K10: 4789.35 | L10: 532.15
A11: Manutan | B11: =SUMIF('OS&E_FF&E'!F:F,'Payment schedule'!A11,'OS&E_FF&E'!H:H) -> 5950 | C11: 100% after delivery | L11: 2720.1
A12: Bunzl | B12: =SUMIF('OS&E_FF&E'!F:F,'Payment schedule'!A12,'OS&E_FF&E'!H:H) -> 3817
A13: Nonius | B13: =SUMIF('OS&E_FF&E'!F:F,'Payment schedule'!A13,'OS&E_FF&E'!H:H) -> 0 | C13: 40% up front, 60% after delivery | H13: 5000 | L13: 7000
A14: Hydrozorg | B14: =Overview!C31 -> 15000
A15: doublestitch | B15: =Overview!C19 -> 5000
A16: deudekom | B16: =Overview!C30 -> 10645
H18: =SUM(H2:H17) -> 13183.85 | I18: =SUM(I2:I17) -> 0 | J18: =SUM(J2:J17) -> 61982.98 | K18: =SUM(K2:K17) -> 41377.07 | L18: =SUM(L2:L17) -> 19678.58 | M18: =SUM(M2:M17) -> 34125.58
